INFO:     Will watch for changes in these directories: ['/Users/alekenov/projects/shadcn-test/backend']
INFO:     Uvicorn running on http://127.0.0.1:8000 (Press CTRL+C to quit)
INFO:     Started reloader process [41169] using WatchFiles
INFO:     Started server process [41173]
INFO:     Waiting for application startup.
INFO:app.main:Starting Cvety.kz API
INFO:app.main:PORT: 8000
INFO:app.main:Environment: development
INFO:app.main:DATABASE_URL from env: NOT SET...
INFO:app.main:DATABASE_URL from settings: sqlite:///./flower_shop.db...
INFO:app.main:Connecting to database: Invalid DATABASE_URL format (length: 26)
INFO:app.db.session:Database engine created successfully: sqlite:///./flower_shop.db...
INFO:app.main:Database tables created successfully
INFO:app.main:Database connection test: OK
INFO:app.services.telegram_service:Telegram bot initialized: @lekenbot
INFO:app.main:Telegram bot polling started
INFO:app.main:Application startup complete
INFO:     Application startup complete.
INFO:app.services.telegram_service:Webhook removed
INFO:app.services.telegram_service:Starting Telegram bot polling...
INFO:aiogram.dispatcher:Start polling
INFO:aiogram.dispatcher:Run polling for bot @lekenbot id=823344503 - 'Доставка цветов по Казахстану'
ERROR:aiogram.dispatcher:Failed to fetch updates - TelegramConflictError: Telegram server says - Conflict: terminated by other getUpdates request; make sure that only one bot instance is running
WARNING:aiogram.dispatcher:Sleep for 1.000000 seconds and try again... (tryings = 0, bot id = 823344503)
ERROR:aiogram.dispatcher:Failed to fetch updates - TelegramConflictError: Telegram server says - Conflict: terminated by other getUpdates request; make sure that only one bot instance is running
WARNING:aiogram.dispatcher:Sleep for 1.344567 seconds and try again... (tryings = 1, bot id = 823344503)
ERROR:aiogram.dispatcher:Failed to fetch updates - TelegramConflictError: Telegram server says - Conflict: terminated by other getUpdates request; make sure that only one bot instance is running
WARNING:aiogram.dispatcher:Sleep for 1.609647 seconds and try again... (tryings = 2, bot id = 823344503)
ERROR:aiogram.dispatcher:Failed to fetch updates - TelegramConflictError: Telegram server says - Conflict: terminated by other getUpdates request; make sure that only one bot instance is running
WARNING:aiogram.dispatcher:Sleep for 2.082339 seconds and try again... (tryings = 3, bot id = 823344503)
ERROR:aiogram.dispatcher:Failed to fetch updates - TelegramConflictError: Telegram server says - Conflict: terminated by other getUpdates request; make sure that only one bot instance is running
WARNING:aiogram.dispatcher:Sleep for 2.727075 seconds and try again... (tryings = 4, bot id = 823344503)
ERROR:aiogram.dispatcher:Failed to fetch updates - TelegramConflictError: Telegram server says - Conflict: terminated by other getUpdates request; make sure that only one bot instance is running
WARNING:aiogram.dispatcher:Sleep for 3.543818 seconds and try again... (tryings = 5, bot id = 823344503)
ERROR:aiogram.dispatcher:Failed to fetch updates - TelegramConflictError: Telegram server says - Conflict: terminated by other getUpdates request; make sure that only one bot instance is running
WARNING:aiogram.dispatcher:Sleep for 4.618446 seconds and try again... (tryings = 6, bot id = 823344503)
ERROR:aiogram.dispatcher:Failed to fetch updates - TelegramConflictError: Telegram server says - Conflict: terminated by other getUpdates request; make sure that only one bot instance is running
WARNING:aiogram.dispatcher:Sleep for 5.032682 seconds and try again... (tryings = 7, bot id = 823344503)
ERROR:aiogram.dispatcher:Failed to fetch updates - TelegramConflictError: Telegram server says - Conflict: terminated by other getUpdates request; make sure that only one bot instance is running
WARNING:aiogram.dispatcher:Sleep for 4.975220 seconds and try again... (tryings = 8, bot id = 823344503)
ERROR:aiogram.dispatcher:Failed to fetch updates - TelegramConflictError: Telegram server says - Conflict: terminated by other getUpdates request; make sure that only one bot instance is running
WARNING:aiogram.dispatcher:Sleep for 4.950199 seconds and try again... (tryings = 9, bot id = 823344503)
ERROR:aiogram.dispatcher:Failed to fetch updates - TelegramConflictError: Telegram server says - Conflict: terminated by other getUpdates request; make sure that only one bot instance is running
WARNING:aiogram.dispatcher:Sleep for 4.900875 seconds and try again... (tryings = 10, bot id = 823344503)
ERROR:aiogram.dispatcher:Failed to fetch updates - TelegramConflictError: Telegram server says - Conflict: terminated by other getUpdates request; make sure that only one bot instance is running
WARNING:aiogram.dispatcher:Sleep for 4.864046 seconds and try again... (tryings = 11, bot id = 823344503)
ERROR:aiogram.dispatcher:Failed to fetch updates - TelegramConflictError: Telegram server says - Conflict: terminated by other getUpdates request; make sure that only one bot instance is running
WARNING:aiogram.dispatcher:Sleep for 5.063348 seconds and try again... (tryings = 12, bot id = 823344503)
ERROR:aiogram.dispatcher:Failed to fetch updates - TelegramConflictError: Telegram server says - Conflict: terminated by other getUpdates request; make sure that only one bot instance is running
WARNING:aiogram.dispatcher:Sleep for 4.979724 seconds and try again... (tryings = 13, bot id = 823344503)
ERROR:aiogram.dispatcher:Failed to fetch updates - TelegramConflictError: Telegram server says - Conflict: terminated by other getUpdates request; make sure that only one bot instance is running
WARNING:aiogram.dispatcher:Sleep for 5.044297 seconds and try again... (tryings = 14, bot id = 823344503)
WARNING:app.services.redis_service:REDIS_URL not found, Redis features will be disabled
INFO:app.services.otp_service:OTP generated for phone: +77771234567
INFO:     127.0.0.1:65307 - "POST /api/auth/request-otp HTTP/1.1" 201 Created
ERROR:aiogram.dispatcher:Failed to fetch updates - TelegramConflictError: Telegram server says - Conflict: terminated by other getUpdates request; make sure that only one bot instance is running
WARNING:aiogram.dispatcher:Sleep for 4.960546 seconds and try again... (tryings = 15, bot id = 823344503)
INFO:     127.0.0.1:65332 - "POST /api/auth/verify-otp HTTP/1.1" 200 OK
INFO:     127.0.0.1:65358 - "GET /api/orders/?limit=2 HTTP/1.1" 403 Forbidden
ERROR:aiogram.dispatcher:Failed to fetch updates - TelegramConflictError: Telegram server says - Conflict: terminated by other getUpdates request; make sure that only one bot instance is running
WARNING:aiogram.dispatcher:Sleep for 4.940431 seconds and try again... (tryings = 16, bot id = 823344503)
INFO:     127.0.0.1:65410 - "GET /api/auth/me HTTP/1.1" 200 OK
INFO:     127.0.0.1:65413 - "GET /api/auth/me HTTP/1.1" 200 OK
INFO:     127.0.0.1:65411 - "GET /api/orders/?page=1&limit=20 HTTP/1.1" 500 Internal Server Error
ERROR:    Exception in ASGI application
Traceback (most recent call last):
  File "/Users/alekenov/Library/Python/3.9/lib/python/site-packages/uvicorn/protocols/http/httptools_impl.py", line 426, in run_asgi
    result = await app(  # type: ignore[func-returns-value]
  File "/Users/alekenov/Library/Python/3.9/lib/python/site-packages/uvicorn/middleware/proxy_headers.py", line 84, in __call__
    return await self.app(scope, receive, send)
  File "/Users/alekenov/Library/Python/3.9/lib/python/site-packages/fastapi/applications.py", line 1054, in __call__
    await super().__call__(scope, receive, send)
  File "/Users/alekenov/Library/Python/3.9/lib/python/site-packages/starlette/applications.py", line 123, in __call__
    await self.middleware_stack(scope, receive, send)
  File "/Users/alekenov/Library/Python/3.9/lib/python/site-packages/starlette/middleware/errors.py", line 186, in __call__
    raise exc
  File "/Users/alekenov/Library/Python/3.9/lib/python/site-packages/starlette/middleware/errors.py", line 164, in __call__
    await self.app(scope, receive, _send)
  File "/Users/alekenov/Library/Python/3.9/lib/python/site-packages/starlette/middleware/cors.py", line 83, in __call__
    await self.app(scope, receive, send)
  File "/Users/alekenov/Library/Python/3.9/lib/python/site-packages/starlette/middleware/exceptions.py", line 62, in __call__
    await wrap_app_handling_exceptions(self.app, conn)(scope, receive, send)
  File "/Users/alekenov/Library/Python/3.9/lib/python/site-packages/starlette/_exception_handler.py", line 64, in wrapped_app
    raise exc
  File "/Users/alekenov/Library/Python/3.9/lib/python/site-packages/starlette/_exception_handler.py", line 53, in wrapped_app
    await app(scope, receive, sender)
  File "/Users/alekenov/Library/Python/3.9/lib/python/site-packages/starlette/routing.py", line 762, in __call__
    await self.middleware_stack(scope, receive, send)
  File "/Users/alekenov/Library/Python/3.9/lib/python/site-packages/starlette/routing.py", line 782, in app
    await route.handle(scope, receive, send)
  File "/Users/alekenov/Library/Python/3.9/lib/python/site-packages/starlette/routing.py", line 297, in handle
    await self.app(scope, receive, send)
  File "/Users/alekenov/Library/Python/3.9/lib/python/site-packages/starlette/routing.py", line 77, in app
    await wrap_app_handling_exceptions(app, request)(scope, receive, send)
  File "/Users/alekenov/Library/Python/3.9/lib/python/site-packages/starlette/_exception_handler.py", line 64, in wrapped_app
    raise exc
  File "/Users/alekenov/Library/Python/3.9/lib/python/site-packages/starlette/_exception_handler.py", line 53, in wrapped_app
    await app(scope, receive, sender)
  File "/Users/alekenov/Library/Python/3.9/lib/python/site-packages/starlette/routing.py", line 72, in app
    response = await func(request)
  File "/Users/alekenov/Library/Python/3.9/lib/python/site-packages/fastapi/routing.py", line 299, in app
    raise e
  File "/Users/alekenov/Library/Python/3.9/lib/python/site-packages/fastapi/routing.py", line 294, in app
    raw_response = await run_endpoint_function(
  File "/Users/alekenov/Library/Python/3.9/lib/python/site-packages/fastapi/routing.py", line 193, in run_endpoint_function
    return await run_in_threadpool(dependant.call, **values)
  File "/Users/alekenov/Library/Python/3.9/lib/python/site-packages/starlette/concurrency.py", line 40, in run_in_threadpool
    return await anyio.to_thread.run_sync(func, *args)
  File "/Users/alekenov/Library/Python/3.9/lib/python/site-packages/anyio/to_thread.py", line 33, in run_sync
    return await get_asynclib().run_sync_in_worker_thread(
  File "/Users/alekenov/Library/Python/3.9/lib/python/site-packages/anyio/_backends/_asyncio.py", line 877, in run_sync_in_worker_thread
    return await future
  File "/Users/alekenov/Library/Python/3.9/lib/python/site-packages/anyio/_backends/_asyncio.py", line 807, in run
    result = context.run(func, *args)
  File "/Users/alekenov/projects/shadcn-test/backend/app/api/endpoints/orders.py", line 72, in get_orders
    'payment_method': order.payment_method,
AttributeError: 'Order' object has no attribute 'payment_method'
ERROR:aiogram.dispatcher:Failed to fetch updates - TelegramConflictError: Telegram server says - Conflict: terminated by other getUpdates request; make sure that only one bot instance is running
WARNING:aiogram.dispatcher:Sleep for 5.014835 seconds and try again... (tryings = 17, bot id = 823344503)
INFO:     127.0.0.1:65416 - "GET /api/orders/?page=1&limit=20 HTTP/1.1" 500 Internal Server Error
ERROR:    Exception in ASGI application
Traceback (most recent call last):
  File "/Users/alekenov/Library/Python/3.9/lib/python/site-packages/uvicorn/protocols/http/httptools_impl.py", line 426, in run_asgi
    result = await app(  # type: ignore[func-returns-value]
  File "/Users/alekenov/Library/Python/3.9/lib/python/site-packages/uvicorn/middleware/proxy_headers.py", line 84, in __call__
    return await self.app(scope, receive, send)
  File "/Users/alekenov/Library/Python/3.9/lib/python/site-packages/fastapi/applications.py", line 1054, in __call__
    await super().__call__(scope, receive, send)
  File "/Users/alekenov/Library/Python/3.9/lib/python/site-packages/starlette/applications.py", line 123, in __call__
    await self.middleware_stack(scope, receive, send)
  File "/Users/alekenov/Library/Python/3.9/lib/python/site-packages/starlette/middleware/errors.py", line 186, in __call__
    raise exc
  File "/Users/alekenov/Library/Python/3.9/lib/python/site-packages/starlette/middleware/errors.py", line 164, in __call__
    await self.app(scope, receive, _send)
  File "/Users/alekenov/Library/Python/3.9/lib/python/site-packages/starlette/middleware/cors.py", line 83, in __call__
    await self.app(scope, receive, send)
  File "/Users/alekenov/Library/Python/3.9/lib/python/site-packages/starlette/middleware/exceptions.py", line 62, in __call__
    await wrap_app_handling_exceptions(self.app, conn)(scope, receive, send)
  File "/Users/alekenov/Library/Python/3.9/lib/python/site-packages/starlette/_exception_handler.py", line 64, in wrapped_app
    raise exc
  File "/Users/alekenov/Library/Python/3.9/lib/python/site-packages/starlette/_exception_handler.py", line 53, in wrapped_app
    await app(scope, receive, sender)
  File "/Users/alekenov/Library/Python/3.9/lib/python/site-packages/starlette/routing.py", line 762, in __call__
    await self.middleware_stack(scope, receive, send)
  File "/Users/alekenov/Library/Python/3.9/lib/python/site-packages/starlette/routing.py", line 782, in app
    await route.handle(scope, receive, send)
  File "/Users/alekenov/Library/Python/3.9/lib/python/site-packages/starlette/routing.py", line 297, in handle
    await self.app(scope, receive, send)
  File "/Users/alekenov/Library/Python/3.9/lib/python/site-packages/starlette/routing.py", line 77, in app
    await wrap_app_handling_exceptions(app, request)(scope, receive, send)
  File "/Users/alekenov/Library/Python/3.9/lib/python/site-packages/starlette/_exception_handler.py", line 64, in wrapped_app
    raise exc
  File "/Users/alekenov/Library/Python/3.9/lib/python/site-packages/starlette/_exception_handler.py", line 53, in wrapped_app
    await app(scope, receive, sender)
  File "/Users/alekenov/Library/Python/3.9/lib/python/site-packages/starlette/routing.py", line 72, in app
    response = await func(request)
  File "/Users/alekenov/Library/Python/3.9/lib/python/site-packages/fastapi/routing.py", line 299, in app
    raise e
  File "/Users/alekenov/Library/Python/3.9/lib/python/site-packages/fastapi/routing.py", line 294, in app
    raw_response = await run_endpoint_function(
  File "/Users/alekenov/Library/Python/3.9/lib/python/site-packages/fastapi/routing.py", line 193, in run_endpoint_function
    return await run_in_threadpool(dependant.call, **values)
  File "/Users/alekenov/Library/Python/3.9/lib/python/site-packages/starlette/concurrency.py", line 40, in run_in_threadpool
    return await anyio.to_thread.run_sync(func, *args)
  File "/Users/alekenov/Library/Python/3.9/lib/python/site-packages/anyio/to_thread.py", line 33, in run_sync
    return await get_asynclib().run_sync_in_worker_thread(
  File "/Users/alekenov/Library/Python/3.9/lib/python/site-packages/anyio/_backends/_asyncio.py", line 877, in run_sync_in_worker_thread
    return await future
  File "/Users/alekenov/Library/Python/3.9/lib/python/site-packages/anyio/_backends/_asyncio.py", line 807, in run
    result = context.run(func, *args)
  File "/Users/alekenov/projects/shadcn-test/backend/app/api/endpoints/orders.py", line 72, in get_orders
    'payment_method': order.payment_method,
AttributeError: 'Order' object has no attribute 'payment_method'
INFO:     127.0.0.1:65418 - "GET /api/orders/?page=1&limit=20 HTTP/1.1" 500 Internal Server Error
ERROR:    Exception in ASGI application
Traceback (most recent call last):
  File "/Users/alekenov/Library/Python/3.9/lib/python/site-packages/uvicorn/protocols/http/httptools_impl.py", line 426, in run_asgi
    result = await app(  # type: ignore[func-returns-value]
  File "/Users/alekenov/Library/Python/3.9/lib/python/site-packages/uvicorn/middleware/proxy_headers.py", line 84, in __call__
    return await self.app(scope, receive, send)
  File "/Users/alekenov/Library/Python/3.9/lib/python/site-packages/fastapi/applications.py", line 1054, in __call__
    await super().__call__(scope, receive, send)
  File "/Users/alekenov/Library/Python/3.9/lib/python/site-packages/starlette/applications.py", line 123, in __call__
    await self.middleware_stack(scope, receive, send)
  File "/Users/alekenov/Library/Python/3.9/lib/python/site-packages/starlette/middleware/errors.py", line 186, in __call__
    raise exc
  File "/Users/alekenov/Library/Python/3.9/lib/python/site-packages/starlette/middleware/errors.py", line 164, in __call__
    await self.app(scope, receive, _send)
  File "/Users/alekenov/Library/Python/3.9/lib/python/site-packages/starlette/middleware/cors.py", line 83, in __call__
    await self.app(scope, receive, send)
  File "/Users/alekenov/Library/Python/3.9/lib/python/site-packages/starlette/middleware/exceptions.py", line 62, in __call__
    await wrap_app_handling_exceptions(self.app, conn)(scope, receive, send)
  File "/Users/alekenov/Library/Python/3.9/lib/python/site-packages/starlette/_exception_handler.py", line 64, in wrapped_app
    raise exc
  File "/Users/alekenov/Library/Python/3.9/lib/python/site-packages/starlette/_exception_handler.py", line 53, in wrapped_app
    await app(scope, receive, sender)
  File "/Users/alekenov/Library/Python/3.9/lib/python/site-packages/starlette/routing.py", line 762, in __call__
    await self.middleware_stack(scope, receive, send)
  File "/Users/alekenov/Library/Python/3.9/lib/python/site-packages/starlette/routing.py", line 782, in app
    await route.handle(scope, receive, send)
  File "/Users/alekenov/Library/Python/3.9/lib/python/site-packages/starlette/routing.py", line 297, in handle
    await self.app(scope, receive, send)
  File "/Users/alekenov/Library/Python/3.9/lib/python/site-packages/starlette/routing.py", line 77, in app
    await wrap_app_handling_exceptions(app, request)(scope, receive, send)
  File "/Users/alekenov/Library/Python/3.9/lib/python/site-packages/starlette/_exception_handler.py", line 64, in wrapped_app
    raise exc
  File "/Users/alekenov/Library/Python/3.9/lib/python/site-packages/starlette/_exception_handler.py", line 53, in wrapped_app
    await app(scope, receive, sender)
  File "/Users/alekenov/Library/Python/3.9/lib/python/site-packages/starlette/routing.py", line 72, in app
    response = await func(request)
  File "/Users/alekenov/Library/Python/3.9/lib/python/site-packages/fastapi/routing.py", line 299, in app
    raise e
  File "/Users/alekenov/Library/Python/3.9/lib/python/site-packages/fastapi/routing.py", line 294, in app
    raw_response = await run_endpoint_function(
  File "/Users/alekenov/Library/Python/3.9/lib/python/site-packages/fastapi/routing.py", line 193, in run_endpoint_function
    return await run_in_threadpool(dependant.call, **values)
  File "/Users/alekenov/Library/Python/3.9/lib/python/site-packages/starlette/concurrency.py", line 40, in run_in_threadpool
    return await anyio.to_thread.run_sync(func, *args)
  File "/Users/alekenov/Library/Python/3.9/lib/python/site-packages/anyio/to_thread.py", line 33, in run_sync
    return await get_asynclib().run_sync_in_worker_thread(
  File "/Users/alekenov/Library/Python/3.9/lib/python/site-packages/anyio/_backends/_asyncio.py", line 877, in run_sync_in_worker_thread
    return await future
  File "/Users/alekenov/Library/Python/3.9/lib/python/site-packages/anyio/_backends/_asyncio.py", line 807, in run
    result = context.run(func, *args)
  File "/Users/alekenov/projects/shadcn-test/backend/app/api/endpoints/orders.py", line 72, in get_orders
    'payment_method': order.payment_method,
AttributeError: 'Order' object has no attribute 'payment_method'
INFO:     127.0.0.1:65425 - "GET /api/orders/?page=1&limit=20 HTTP/1.1" 500 Internal Server Error
ERROR:    Exception in ASGI application
Traceback (most recent call last):
  File "/Users/alekenov/Library/Python/3.9/lib/python/site-packages/uvicorn/protocols/http/httptools_impl.py", line 426, in run_asgi
    result = await app(  # type: ignore[func-returns-value]
  File "/Users/alekenov/Library/Python/3.9/lib/python/site-packages/uvicorn/middleware/proxy_headers.py", line 84, in __call__
    return await self.app(scope, receive, send)
  File "/Users/alekenov/Library/Python/3.9/lib/python/site-packages/fastapi/applications.py", line 1054, in __call__
    await super().__call__(scope, receive, send)
  File "/Users/alekenov/Library/Python/3.9/lib/python/site-packages/starlette/applications.py", line 123, in __call__
    await self.middleware_stack(scope, receive, send)
  File "/Users/alekenov/Library/Python/3.9/lib/python/site-packages/starlette/middleware/errors.py", line 186, in __call__
    raise exc
  File "/Users/alekenov/Library/Python/3.9/lib/python/site-packages/starlette/middleware/errors.py", line 164, in __call__
    await self.app(scope, receive, _send)
  File "/Users/alekenov/Library/Python/3.9/lib/python/site-packages/starlette/middleware/cors.py", line 83, in __call__
    await self.app(scope, receive, send)
  File "/Users/alekenov/Library/Python/3.9/lib/python/site-packages/starlette/middleware/exceptions.py", line 62, in __call__
    await wrap_app_handling_exceptions(self.app, conn)(scope, receive, send)
  File "/Users/alekenov/Library/Python/3.9/lib/python/site-packages/starlette/_exception_handler.py", line 64, in wrapped_app
    raise exc
  File "/Users/alekenov/Library/Python/3.9/lib/python/site-packages/starlette/_exception_handler.py", line 53, in wrapped_app
    await app(scope, receive, sender)
  File "/Users/alekenov/Library/Python/3.9/lib/python/site-packages/starlette/routing.py", line 762, in __call__
    await self.middleware_stack(scope, receive, send)
  File "/Users/alekenov/Library/Python/3.9/lib/python/site-packages/starlette/routing.py", line 782, in app
    await route.handle(scope, receive, send)
  File "/Users/alekenov/Library/Python/3.9/lib/python/site-packages/starlette/routing.py", line 297, in handle
    await self.app(scope, receive, send)
  File "/Users/alekenov/Library/Python/3.9/lib/python/site-packages/starlette/routing.py", line 77, in app
    await wrap_app_handling_exceptions(app, request)(scope, receive, send)
  File "/Users/alekenov/Library/Python/3.9/lib/python/site-packages/starlette/_exception_handler.py", line 64, in wrapped_app
    raise exc
  File "/Users/alekenov/Library/Python/3.9/lib/python/site-packages/starlette/_exception_handler.py", line 53, in wrapped_app
    await app(scope, receive, sender)
  File "/Users/alekenov/Library/Python/3.9/lib/python/site-packages/starlette/routing.py", line 72, in app
    response = await func(request)
  File "/Users/alekenov/Library/Python/3.9/lib/python/site-packages/fastapi/routing.py", line 299, in app
    raise e
  File "/Users/alekenov/Library/Python/3.9/lib/python/site-packages/fastapi/routing.py", line 294, in app
    raw_response = await run_endpoint_function(
  File "/Users/alekenov/Library/Python/3.9/lib/python/site-packages/fastapi/routing.py", line 193, in run_endpoint_function
    return await run_in_threadpool(dependant.call, **values)
  File "/Users/alekenov/Library/Python/3.9/lib/python/site-packages/starlette/concurrency.py", line 40, in run_in_threadpool
    return await anyio.to_thread.run_sync(func, *args)
  File "/Users/alekenov/Library/Python/3.9/lib/python/site-packages/anyio/to_thread.py", line 33, in run_sync
    return await get_asynclib().run_sync_in_worker_thread(
  File "/Users/alekenov/Library/Python/3.9/lib/python/site-packages/anyio/_backends/_asyncio.py", line 877, in run_sync_in_worker_thread
    return await future
  File "/Users/alekenov/Library/Python/3.9/lib/python/site-packages/anyio/_backends/_asyncio.py", line 807, in run
    result = context.run(func, *args)
  File "/Users/alekenov/projects/shadcn-test/backend/app/api/endpoints/orders.py", line 72, in get_orders
    'payment_method': order.payment_method,
AttributeError: 'Order' object has no attribute 'payment_method'
ERROR:aiogram.dispatcher:Failed to fetch updates - TelegramConflictError: Telegram server says - Conflict: terminated by other getUpdates request; make sure that only one bot instance is running
WARNING:aiogram.dispatcher:Sleep for 4.920088 seconds and try again... (tryings = 18, bot id = 823344503)
ERROR:aiogram.dispatcher:Failed to fetch updates - TelegramConflictError: Telegram server says - Conflict: terminated by other getUpdates request; make sure that only one bot instance is running
WARNING:aiogram.dispatcher:Sleep for 4.887990 seconds and try again... (tryings = 19, bot id = 823344503)
ERROR:aiogram.dispatcher:Failed to fetch updates - TelegramConflictError: Telegram server says - Conflict: terminated by other getUpdates request; make sure that only one bot instance is running
WARNING:aiogram.dispatcher:Sleep for 5.120410 seconds and try again... (tryings = 20, bot id = 823344503)
WARNING:  WatchFiles detected changes in 'app/api/endpoints/orders.py'. Reloading...
WARNING:aiogram.dispatcher:Received SIGTERM signal
INFO:aiogram.dispatcher:Polling stopped for bot @lekenbot id=823344503 - 'Доставка цветов по Казахстану'
INFO:aiogram.dispatcher:Polling stopped
INFO:     127.0.0.1:49169 - "GET /api/auth/me HTTP/1.1" 200 OK
INFO:     127.0.0.1:49171 - "GET /api/auth/me HTTP/1.1" 200 OK
INFO:     127.0.0.1:49168 - "GET /api/orders/?page=1&limit=20 HTTP/1.1" 500 Internal Server Error
ERROR:    Exception in ASGI application
Traceback (most recent call last):
  File "/Users/alekenov/Library/Python/3.9/lib/python/site-packages/uvicorn/protocols/http/httptools_impl.py", line 426, in run_asgi
    result = await app(  # type: ignore[func-returns-value]
  File "/Users/alekenov/Library/Python/3.9/lib/python/site-packages/uvicorn/middleware/proxy_headers.py", line 84, in __call__
    return await self.app(scope, receive, send)
  File "/Users/alekenov/Library/Python/3.9/lib/python/site-packages/fastapi/applications.py", line 1054, in __call__
    await super().__call__(scope, receive, send)
  File "/Users/alekenov/Library/Python/3.9/lib/python/site-packages/starlette/applications.py", line 123, in __call__
    await self.middleware_stack(scope, receive, send)
  File "/Users/alekenov/Library/Python/3.9/lib/python/site-packages/starlette/middleware/errors.py", line 186, in __call__
    raise exc
  File "/Users/alekenov/Library/Python/3.9/lib/python/site-packages/starlette/middleware/errors.py", line 164, in __call__
    await self.app(scope, receive, _send)
  File "/Users/alekenov/Library/Python/3.9/lib/python/site-packages/starlette/middleware/cors.py", line 83, in __call__
    await self.app(scope, receive, send)
  File "/Users/alekenov/Library/Python/3.9/lib/python/site-packages/starlette/middleware/exceptions.py", line 62, in __call__
    await wrap_app_handling_exceptions(self.app, conn)(scope, receive, send)
  File "/Users/alekenov/Library/Python/3.9/lib/python/site-packages/starlette/_exception_handler.py", line 64, in wrapped_app
    raise exc
  File "/Users/alekenov/Library/Python/3.9/lib/python/site-packages/starlette/_exception_handler.py", line 53, in wrapped_app
    await app(scope, receive, sender)
  File "/Users/alekenov/Library/Python/3.9/lib/python/site-packages/starlette/routing.py", line 762, in __call__
    await self.middleware_stack(scope, receive, send)
  File "/Users/alekenov/Library/Python/3.9/lib/python/site-packages/starlette/routing.py", line 782, in app
    await route.handle(scope, receive, send)
  File "/Users/alekenov/Library/Python/3.9/lib/python/site-packages/starlette/routing.py", line 297, in handle
    await self.app(scope, receive, send)
  File "/Users/alekenov/Library/Python/3.9/lib/python/site-packages/starlette/routing.py", line 77, in app
    await wrap_app_handling_exceptions(app, request)(scope, receive, send)
  File "/Users/alekenov/Library/Python/3.9/lib/python/site-packages/starlette/_exception_handler.py", line 64, in wrapped_app
    raise exc
  File "/Users/alekenov/Library/Python/3.9/lib/python/site-packages/starlette/_exception_handler.py", line 53, in wrapped_app
    await app(scope, receive, sender)
  File "/Users/alekenov/Library/Python/3.9/lib/python/site-packages/starlette/routing.py", line 72, in app
    response = await func(request)
  File "/Users/alekenov/Library/Python/3.9/lib/python/site-packages/fastapi/routing.py", line 299, in app
    raise e
  File "/Users/alekenov/Library/Python/3.9/lib/python/site-packages/fastapi/routing.py", line 294, in app
    raw_response = await run_endpoint_function(
  File "/Users/alekenov/Library/Python/3.9/lib/python/site-packages/fastapi/routing.py", line 193, in run_endpoint_function
    return await run_in_threadpool(dependant.call, **values)
  File "/Users/alekenov/Library/Python/3.9/lib/python/site-packages/starlette/concurrency.py", line 40, in run_in_threadpool
    return await anyio.to_thread.run_sync(func, *args)
  File "/Users/alekenov/Library/Python/3.9/lib/python/site-packages/anyio/to_thread.py", line 33, in run_sync
    return await get_asynclib().run_sync_in_worker_thread(
  File "/Users/alekenov/Library/Python/3.9/lib/python/site-packages/anyio/_backends/_asyncio.py", line 877, in run_sync_in_worker_thread
    return await future
  File "/Users/alekenov/Library/Python/3.9/lib/python/site-packages/anyio/_backends/_asyncio.py", line 807, in run
    result = context.run(func, *args)
  File "/Users/alekenov/projects/shadcn-test/backend/app/api/endpoints/orders.py", line 72, in get_orders
    'tracking_token': order.tracking_token,
AttributeError: 'Order' object has no attribute 'payment_method'
INFO:     127.0.0.1:49173 - "GET /api/orders/?page=1&limit=20 HTTP/1.1" 500 Internal Server Error
ERROR:    Exception in ASGI application
Traceback (most recent call last):
  File "/Users/alekenov/Library/Python/3.9/lib/python/site-packages/uvicorn/protocols/http/httptools_impl.py", line 426, in run_asgi
    result = await app(  # type: ignore[func-returns-value]
  File "/Users/alekenov/Library/Python/3.9/lib/python/site-packages/uvicorn/middleware/proxy_headers.py", line 84, in __call__
    return await self.app(scope, receive, send)
  File "/Users/alekenov/Library/Python/3.9/lib/python/site-packages/fastapi/applications.py", line 1054, in __call__
    await super().__call__(scope, receive, send)
  File "/Users/alekenov/Library/Python/3.9/lib/python/site-packages/starlette/applications.py", line 123, in __call__
    await self.middleware_stack(scope, receive, send)
  File "/Users/alekenov/Library/Python/3.9/lib/python/site-packages/starlette/middleware/errors.py", line 186, in __call__
    raise exc
  File "/Users/alekenov/Library/Python/3.9/lib/python/site-packages/starlette/middleware/errors.py", line 164, in __call__
    await self.app(scope, receive, _send)
  File "/Users/alekenov/Library/Python/3.9/lib/python/site-packages/starlette/middleware/cors.py", line 83, in __call__
    await self.app(scope, receive, send)
  File "/Users/alekenov/Library/Python/3.9/lib/python/site-packages/starlette/middleware/exceptions.py", line 62, in __call__
    await wrap_app_handling_exceptions(self.app, conn)(scope, receive, send)
  File "/Users/alekenov/Library/Python/3.9/lib/python/site-packages/starlette/_exception_handler.py", line 64, in wrapped_app
    raise exc
  File "/Users/alekenov/Library/Python/3.9/lib/python/site-packages/starlette/_exception_handler.py", line 53, in wrapped_app
    await app(scope, receive, sender)
  File "/Users/alekenov/Library/Python/3.9/lib/python/site-packages/starlette/routing.py", line 762, in __call__
    await self.middleware_stack(scope, receive, send)
  File "/Users/alekenov/Library/Python/3.9/lib/python/site-packages/starlette/routing.py", line 782, in app
    await route.handle(scope, receive, send)
  File "/Users/alekenov/Library/Python/3.9/lib/python/site-packages/starlette/routing.py", line 297, in handle
    await self.app(scope, receive, send)
  File "/Users/alekenov/Library/Python/3.9/lib/python/site-packages/starlette/routing.py", line 77, in app
    await wrap_app_handling_exceptions(app, request)(scope, receive, send)
  File "/Users/alekenov/Library/Python/3.9/lib/python/site-packages/starlette/_exception_handler.py", line 64, in wrapped_app
    raise exc
  File "/Users/alekenov/Library/Python/3.9/lib/python/site-packages/starlette/_exception_handler.py", line 53, in wrapped_app
    await app(scope, receive, sender)
  File "/Users/alekenov/Library/Python/3.9/lib/python/site-packages/starlette/routing.py", line 72, in app
    response = await func(request)
  File "/Users/alekenov/Library/Python/3.9/lib/python/site-packages/fastapi/routing.py", line 299, in app
    raise e
  File "/Users/alekenov/Library/Python/3.9/lib/python/site-packages/fastapi/routing.py", line 294, in app
    raw_response = await run_endpoint_function(
  File "/Users/alekenov/Library/Python/3.9/lib/python/site-packages/fastapi/routing.py", line 193, in run_endpoint_function
    return await run_in_threadpool(dependant.call, **values)
  File "/Users/alekenov/Library/Python/3.9/lib/python/site-packages/starlette/concurrency.py", line 40, in run_in_threadpool
    return await anyio.to_thread.run_sync(func, *args)
  File "/Users/alekenov/Library/Python/3.9/lib/python/site-packages/anyio/to_thread.py", line 33, in run_sync
    return await get_asynclib().run_sync_in_worker_thread(
  File "/Users/alekenov/Library/Python/3.9/lib/python/site-packages/anyio/_backends/_asyncio.py", line 877, in run_sync_in_worker_thread
    return await future
  File "/Users/alekenov/Library/Python/3.9/lib/python/site-packages/anyio/_backends/_asyncio.py", line 807, in run
    result = context.run(func, *args)
  File "/Users/alekenov/projects/shadcn-test/backend/app/api/endpoints/orders.py", line 72, in get_orders
    'tracking_token': order.tracking_token,
AttributeError: 'Order' object has no attribute 'payment_method'
INFO:     127.0.0.1:49176 - "GET /api/orders/?page=1&limit=20 HTTP/1.1" 500 Internal Server Error
ERROR:    Exception in ASGI application
Traceback (most recent call last):
  File "/Users/alekenov/Library/Python/3.9/lib/python/site-packages/uvicorn/protocols/http/httptools_impl.py", line 426, in run_asgi
    result = await app(  # type: ignore[func-returns-value]
  File "/Users/alekenov/Library/Python/3.9/lib/python/site-packages/uvicorn/middleware/proxy_headers.py", line 84, in __call__
    return await self.app(scope, receive, send)
  File "/Users/alekenov/Library/Python/3.9/lib/python/site-packages/fastapi/applications.py", line 1054, in __call__
    await super().__call__(scope, receive, send)
  File "/Users/alekenov/Library/Python/3.9/lib/python/site-packages/starlette/applications.py", line 123, in __call__
    await self.middleware_stack(scope, receive, send)
  File "/Users/alekenov/Library/Python/3.9/lib/python/site-packages/starlette/middleware/errors.py", line 186, in __call__
    raise exc
  File "/Users/alekenov/Library/Python/3.9/lib/python/site-packages/starlette/middleware/errors.py", line 164, in __call__
    await self.app(scope, receive, _send)
  File "/Users/alekenov/Library/Python/3.9/lib/python/site-packages/starlette/middleware/cors.py", line 83, in __call__
    await self.app(scope, receive, send)
  File "/Users/alekenov/Library/Python/3.9/lib/python/site-packages/starlette/middleware/exceptions.py", line 62, in __call__
    await wrap_app_handling_exceptions(self.app, conn)(scope, receive, send)
  File "/Users/alekenov/Library/Python/3.9/lib/python/site-packages/starlette/_exception_handler.py", line 64, in wrapped_app
    raise exc
  File "/Users/alekenov/Library/Python/3.9/lib/python/site-packages/starlette/_exception_handler.py", line 53, in wrapped_app
    await app(scope, receive, sender)
  File "/Users/alekenov/Library/Python/3.9/lib/python/site-packages/starlette/routing.py", line 762, in __call__
    await self.middleware_stack(scope, receive, send)
  File "/Users/alekenov/Library/Python/3.9/lib/python/site-packages/starlette/routing.py", line 782, in app
    await route.handle(scope, receive, send)
  File "/Users/alekenov/Library/Python/3.9/lib/python/site-packages/starlette/routing.py", line 297, in handle
    await self.app(scope, receive, send)
  File "/Users/alekenov/Library/Python/3.9/lib/python/site-packages/starlette/routing.py", line 77, in app
    await wrap_app_handling_exceptions(app, request)(scope, receive, send)
  File "/Users/alekenov/Library/Python/3.9/lib/python/site-packages/starlette/_exception_handler.py", line 64, in wrapped_app
    raise exc
  File "/Users/alekenov/Library/Python/3.9/lib/python/site-packages/starlette/_exception_handler.py", line 53, in wrapped_app
    await app(scope, receive, sender)
  File "/Users/alekenov/Library/Python/3.9/lib/python/site-packages/starlette/routing.py", line 72, in app
    response = await func(request)
  File "/Users/alekenov/Library/Python/3.9/lib/python/site-packages/fastapi/routing.py", line 299, in app
    raise e
  File "/Users/alekenov/Library/Python/3.9/lib/python/site-packages/fastapi/routing.py", line 294, in app
    raw_response = await run_endpoint_function(
  File "/Users/alekenov/Library/Python/3.9/lib/python/site-packages/fastapi/routing.py", line 193, in run_endpoint_function
    return await run_in_threadpool(dependant.call, **values)
  File "/Users/alekenov/Library/Python/3.9/lib/python/site-packages/starlette/concurrency.py", line 40, in run_in_threadpool
    return await anyio.to_thread.run_sync(func, *args)
  File "/Users/alekenov/Library/Python/3.9/lib/python/site-packages/anyio/to_thread.py", line 33, in run_sync
    return await get_asynclib().run_sync_in_worker_thread(
  File "/Users/alekenov/Library/Python/3.9/lib/python/site-packages/anyio/_backends/_asyncio.py", line 877, in run_sync_in_worker_thread
    return await future
  File "/Users/alekenov/Library/Python/3.9/lib/python/site-packages/anyio/_backends/_asyncio.py", line 807, in run
    result = context.run(func, *args)
  File "/Users/alekenov/projects/shadcn-test/backend/app/api/endpoints/orders.py", line 72, in get_orders
    'tracking_token': order.tracking_token,
AttributeError: 'Order' object has no attribute 'payment_method'
INFO:     127.0.0.1:49191 - "GET /api/auth/me HTTP/1.1" 200 OK
INFO:     127.0.0.1:49193 - "GET /api/auth/me HTTP/1.1" 200 OK
INFO:     127.0.0.1:49190 - "GET /api/orders/?page=1&limit=20 HTTP/1.1" 500 Internal Server Error
ERROR:    Exception in ASGI application
Traceback (most recent call last):
  File "/Users/alekenov/Library/Python/3.9/lib/python/site-packages/uvicorn/protocols/http/httptools_impl.py", line 426, in run_asgi
    result = await app(  # type: ignore[func-returns-value]
  File "/Users/alekenov/Library/Python/3.9/lib/python/site-packages/uvicorn/middleware/proxy_headers.py", line 84, in __call__
    return await self.app(scope, receive, send)
  File "/Users/alekenov/Library/Python/3.9/lib/python/site-packages/fastapi/applications.py", line 1054, in __call__
    await super().__call__(scope, receive, send)
  File "/Users/alekenov/Library/Python/3.9/lib/python/site-packages/starlette/applications.py", line 123, in __call__
    await self.middleware_stack(scope, receive, send)
  File "/Users/alekenov/Library/Python/3.9/lib/python/site-packages/starlette/middleware/errors.py", line 186, in __call__
    raise exc
  File "/Users/alekenov/Library/Python/3.9/lib/python/site-packages/starlette/middleware/errors.py", line 164, in __call__
    await self.app(scope, receive, _send)
  File "/Users/alekenov/Library/Python/3.9/lib/python/site-packages/starlette/middleware/cors.py", line 83, in __call__
    await self.app(scope, receive, send)
  File "/Users/alekenov/Library/Python/3.9/lib/python/site-packages/starlette/middleware/exceptions.py", line 62, in __call__
    await wrap_app_handling_exceptions(self.app, conn)(scope, receive, send)
  File "/Users/alekenov/Library/Python/3.9/lib/python/site-packages/starlette/_exception_handler.py", line 64, in wrapped_app
    raise exc
  File "/Users/alekenov/Library/Python/3.9/lib/python/site-packages/starlette/_exception_handler.py", line 53, in wrapped_app
    await app(scope, receive, sender)
  File "/Users/alekenov/Library/Python/3.9/lib/python/site-packages/starlette/routing.py", line 762, in __call__
    await self.middleware_stack(scope, receive, send)
  File "/Users/alekenov/Library/Python/3.9/lib/python/site-packages/starlette/routing.py", line 782, in app
    await route.handle(scope, receive, send)
  File "/Users/alekenov/Library/Python/3.9/lib/python/site-packages/starlette/routing.py", line 297, in handle
    await self.app(scope, receive, send)
  File "/Users/alekenov/Library/Python/3.9/lib/python/site-packages/starlette/routing.py", line 77, in app
    await wrap_app_handling_exceptions(app, request)(scope, receive, send)
  File "/Users/alekenov/Library/Python/3.9/lib/python/site-packages/starlette/_exception_handler.py", line 64, in wrapped_app
    raise exc
  File "/Users/alekenov/Library/Python/3.9/lib/python/site-packages/starlette/_exception_handler.py", line 53, in wrapped_app
    await app(scope, receive, sender)
  File "/Users/alekenov/Library/Python/3.9/lib/python/site-packages/starlette/routing.py", line 72, in app
    response = await func(request)
  File "/Users/alekenov/Library/Python/3.9/lib/python/site-packages/fastapi/routing.py", line 299, in app
    raise e
  File "/Users/alekenov/Library/Python/3.9/lib/python/site-packages/fastapi/routing.py", line 294, in app
    raw_response = await run_endpoint_function(
  File "/Users/alekenov/Library/Python/3.9/lib/python/site-packages/fastapi/routing.py", line 193, in run_endpoint_function
    return await run_in_threadpool(dependant.call, **values)
  File "/Users/alekenov/Library/Python/3.9/lib/python/site-packages/starlette/concurrency.py", line 40, in run_in_threadpool
    return await anyio.to_thread.run_sync(func, *args)
  File "/Users/alekenov/Library/Python/3.9/lib/python/site-packages/anyio/to_thread.py", line 33, in run_sync
    return await get_asynclib().run_sync_in_worker_thread(
  File "/Users/alekenov/Library/Python/3.9/lib/python/site-packages/anyio/_backends/_asyncio.py", line 877, in run_sync_in_worker_thread
    return await future
  File "/Users/alekenov/Library/Python/3.9/lib/python/site-packages/anyio/_backends/_asyncio.py", line 807, in run
    result = context.run(func, *args)
  File "/Users/alekenov/projects/shadcn-test/backend/app/api/endpoints/orders.py", line 72, in get_orders
    'tracking_token': order.tracking_token,
AttributeError: 'Order' object has no attribute 'payment_method'
INFO:     127.0.0.1:49208 - "GET /api/orders/?page=1&limit=20 HTTP/1.1" 500 Internal Server Error
ERROR:    Exception in ASGI application
Traceback (most recent call last):
  File "/Users/alekenov/Library/Python/3.9/lib/python/site-packages/uvicorn/protocols/http/httptools_impl.py", line 426, in run_asgi
    result = await app(  # type: ignore[func-returns-value]
  File "/Users/alekenov/Library/Python/3.9/lib/python/site-packages/uvicorn/middleware/proxy_headers.py", line 84, in __call__
    return await self.app(scope, receive, send)
  File "/Users/alekenov/Library/Python/3.9/lib/python/site-packages/fastapi/applications.py", line 1054, in __call__
    await super().__call__(scope, receive, send)
  File "/Users/alekenov/Library/Python/3.9/lib/python/site-packages/starlette/applications.py", line 123, in __call__
    await self.middleware_stack(scope, receive, send)
  File "/Users/alekenov/Library/Python/3.9/lib/python/site-packages/starlette/middleware/errors.py", line 186, in __call__
    raise exc
  File "/Users/alekenov/Library/Python/3.9/lib/python/site-packages/starlette/middleware/errors.py", line 164, in __call__
    await self.app(scope, receive, _send)
  File "/Users/alekenov/Library/Python/3.9/lib/python/site-packages/starlette/middleware/cors.py", line 83, in __call__
    await self.app(scope, receive, send)
  File "/Users/alekenov/Library/Python/3.9/lib/python/site-packages/starlette/middleware/exceptions.py", line 62, in __call__
    await wrap_app_handling_exceptions(self.app, conn)(scope, receive, send)
  File "/Users/alekenov/Library/Python/3.9/lib/python/site-packages/starlette/_exception_handler.py", line 64, in wrapped_app
    raise exc
  File "/Users/alekenov/Library/Python/3.9/lib/python/site-packages/starlette/_exception_handler.py", line 53, in wrapped_app
    await app(scope, receive, sender)
  File "/Users/alekenov/Library/Python/3.9/lib/python/site-packages/starlette/routing.py", line 762, in __call__
    await self.middleware_stack(scope, receive, send)
  File "/Users/alekenov/Library/Python/3.9/lib/python/site-packages/starlette/routing.py", line 782, in app
    await route.handle(scope, receive, send)
  File "/Users/alekenov/Library/Python/3.9/lib/python/site-packages/starlette/routing.py", line 297, in handle
    await self.app(scope, receive, send)
  File "/Users/alekenov/Library/Python/3.9/lib/python/site-packages/starlette/routing.py", line 77, in app
    await wrap_app_handling_exceptions(app, request)(scope, receive, send)
  File "/Users/alekenov/Library/Python/3.9/lib/python/site-packages/starlette/_exception_handler.py", line 64, in wrapped_app
    raise exc
  File "/Users/alekenov/Library/Python/3.9/lib/python/site-packages/starlette/_exception_handler.py", line 53, in wrapped_app
    await app(scope, receive, sender)
  File "/Users/alekenov/Library/Python/3.9/lib/python/site-packages/starlette/routing.py", line 72, in app
    response = await func(request)
  File "/Users/alekenov/Library/Python/3.9/lib/python/site-packages/fastapi/routing.py", line 299, in app
    raise e
  File "/Users/alekenov/Library/Python/3.9/lib/python/site-packages/fastapi/routing.py", line 294, in app
    raw_response = await run_endpoint_function(
  File "/Users/alekenov/Library/Python/3.9/lib/python/site-packages/fastapi/routing.py", line 193, in run_endpoint_function
    return await run_in_threadpool(dependant.call, **values)
  File "/Users/alekenov/Library/Python/3.9/lib/python/site-packages/starlette/concurrency.py", line 40, in run_in_threadpool
    return await anyio.to_thread.run_sync(func, *args)
  File "/Users/alekenov/Library/Python/3.9/lib/python/site-packages/anyio/to_thread.py", line 33, in run_sync
    return await get_asynclib().run_sync_in_worker_thread(
  File "/Users/alekenov/Library/Python/3.9/lib/python/site-packages/anyio/_backends/_asyncio.py", line 877, in run_sync_in_worker_thread
    return await future
  File "/Users/alekenov/Library/Python/3.9/lib/python/site-packages/anyio/_backends/_asyncio.py", line 807, in run
    result = context.run(func, *args)
  File "/Users/alekenov/projects/shadcn-test/backend/app/api/endpoints/orders.py", line 72, in get_orders
    'tracking_token': order.tracking_token,
AttributeError: 'Order' object has no attribute 'payment_method'
INFO:     127.0.0.1:49211 - "GET /api/orders/?page=1&limit=20 HTTP/1.1" 500 Internal Server Error
ERROR:    Exception in ASGI application
Traceback (most recent call last):
  File "/Users/alekenov/Library/Python/3.9/lib/python/site-packages/uvicorn/protocols/http/httptools_impl.py", line 426, in run_asgi
    result = await app(  # type: ignore[func-returns-value]
  File "/Users/alekenov/Library/Python/3.9/lib/python/site-packages/uvicorn/middleware/proxy_headers.py", line 84, in __call__
    return await self.app(scope, receive, send)
  File "/Users/alekenov/Library/Python/3.9/lib/python/site-packages/fastapi/applications.py", line 1054, in __call__
    await super().__call__(scope, receive, send)
  File "/Users/alekenov/Library/Python/3.9/lib/python/site-packages/starlette/applications.py", line 123, in __call__
    await self.middleware_stack(scope, receive, send)
  File "/Users/alekenov/Library/Python/3.9/lib/python/site-packages/starlette/middleware/errors.py", line 186, in __call__
    raise exc
  File "/Users/alekenov/Library/Python/3.9/lib/python/site-packages/starlette/middleware/errors.py", line 164, in __call__
    await self.app(scope, receive, _send)
  File "/Users/alekenov/Library/Python/3.9/lib/python/site-packages/starlette/middleware/cors.py", line 83, in __call__
    await self.app(scope, receive, send)
  File "/Users/alekenov/Library/Python/3.9/lib/python/site-packages/starlette/middleware/exceptions.py", line 62, in __call__
    await wrap_app_handling_exceptions(self.app, conn)(scope, receive, send)
  File "/Users/alekenov/Library/Python/3.9/lib/python/site-packages/starlette/_exception_handler.py", line 64, in wrapped_app
    raise exc
  File "/Users/alekenov/Library/Python/3.9/lib/python/site-packages/starlette/_exception_handler.py", line 53, in wrapped_app
    await app(scope, receive, sender)
  File "/Users/alekenov/Library/Python/3.9/lib/python/site-packages/starlette/routing.py", line 762, in __call__
    await self.middleware_stack(scope, receive, send)
  File "/Users/alekenov/Library/Python/3.9/lib/python/site-packages/starlette/routing.py", line 782, in app
    await route.handle(scope, receive, send)
  File "/Users/alekenov/Library/Python/3.9/lib/python/site-packages/starlette/routing.py", line 297, in handle
    await self.app(scope, receive, send)
  File "/Users/alekenov/Library/Python/3.9/lib/python/site-packages/starlette/routing.py", line 77, in app
    await wrap_app_handling_exceptions(app, request)(scope, receive, send)
  File "/Users/alekenov/Library/Python/3.9/lib/python/site-packages/starlette/_exception_handler.py", line 64, in wrapped_app
    raise exc
  File "/Users/alekenov/Library/Python/3.9/lib/python/site-packages/starlette/_exception_handler.py", line 53, in wrapped_app
    await app(scope, receive, sender)
  File "/Users/alekenov/Library/Python/3.9/lib/python/site-packages/starlette/routing.py", line 72, in app
    response = await func(request)
  File "/Users/alekenov/Library/Python/3.9/lib/python/site-packages/fastapi/routing.py", line 299, in app
    raise e
  File "/Users/alekenov/Library/Python/3.9/lib/python/site-packages/fastapi/routing.py", line 294, in app
    raw_response = await run_endpoint_function(
  File "/Users/alekenov/Library/Python/3.9/lib/python/site-packages/fastapi/routing.py", line 193, in run_endpoint_function
    return await run_in_threadpool(dependant.call, **values)
  File "/Users/alekenov/Library/Python/3.9/lib/python/site-packages/starlette/concurrency.py", line 40, in run_in_threadpool
    return await anyio.to_thread.run_sync(func, *args)
  File "/Users/alekenov/Library/Python/3.9/lib/python/site-packages/anyio/to_thread.py", line 33, in run_sync
    return await get_asynclib().run_sync_in_worker_thread(
  File "/Users/alekenov/Library/Python/3.9/lib/python/site-packages/anyio/_backends/_asyncio.py", line 877, in run_sync_in_worker_thread
    return await future
  File "/Users/alekenov/Library/Python/3.9/lib/python/site-packages/anyio/_backends/_asyncio.py", line 807, in run
    result = context.run(func, *args)
  File "/Users/alekenov/projects/shadcn-test/backend/app/api/endpoints/orders.py", line 72, in get_orders
    'tracking_token': order.tracking_token,
AttributeError: 'Order' object has no attribute 'payment_method'
INFO:     127.0.0.1:49214 - "GET /api/orders/?page=1&limit=20 HTTP/1.1" 500 Internal Server Error
ERROR:    Exception in ASGI application
Traceback (most recent call last):
  File "/Users/alekenov/Library/Python/3.9/lib/python/site-packages/uvicorn/protocols/http/httptools_impl.py", line 426, in run_asgi
    result = await app(  # type: ignore[func-returns-value]
  File "/Users/alekenov/Library/Python/3.9/lib/python/site-packages/uvicorn/middleware/proxy_headers.py", line 84, in __call__
    return await self.app(scope, receive, send)
  File "/Users/alekenov/Library/Python/3.9/lib/python/site-packages/fastapi/applications.py", line 1054, in __call__
    await super().__call__(scope, receive, send)
  File "/Users/alekenov/Library/Python/3.9/lib/python/site-packages/starlette/applications.py", line 123, in __call__
    await self.middleware_stack(scope, receive, send)
  File "/Users/alekenov/Library/Python/3.9/lib/python/site-packages/starlette/middleware/errors.py", line 186, in __call__
    raise exc
  File "/Users/alekenov/Library/Python/3.9/lib/python/site-packages/starlette/middleware/errors.py", line 164, in __call__
    await self.app(scope, receive, _send)
  File "/Users/alekenov/Library/Python/3.9/lib/python/site-packages/starlette/middleware/cors.py", line 83, in __call__
    await self.app(scope, receive, send)
  File "/Users/alekenov/Library/Python/3.9/lib/python/site-packages/starlette/middleware/exceptions.py", line 62, in __call__
    await wrap_app_handling_exceptions(self.app, conn)(scope, receive, send)
  File "/Users/alekenov/Library/Python/3.9/lib/python/site-packages/starlette/_exception_handler.py", line 64, in wrapped_app
    raise exc
  File "/Users/alekenov/Library/Python/3.9/lib/python/site-packages/starlette/_exception_handler.py", line 53, in wrapped_app
    await app(scope, receive, sender)
  File "/Users/alekenov/Library/Python/3.9/lib/python/site-packages/starlette/routing.py", line 762, in __call__
    await self.middleware_stack(scope, receive, send)
  File "/Users/alekenov/Library/Python/3.9/lib/python/site-packages/starlette/routing.py", line 782, in app
    await route.handle(scope, receive, send)
  File "/Users/alekenov/Library/Python/3.9/lib/python/site-packages/starlette/routing.py", line 297, in handle
    await self.app(scope, receive, send)
  File "/Users/alekenov/Library/Python/3.9/lib/python/site-packages/starlette/routing.py", line 77, in app
    await wrap_app_handling_exceptions(app, request)(scope, receive, send)
  File "/Users/alekenov/Library/Python/3.9/lib/python/site-packages/starlette/_exception_handler.py", line 64, in wrapped_app
    raise exc
  File "/Users/alekenov/Library/Python/3.9/lib/python/site-packages/starlette/_exception_handler.py", line 53, in wrapped_app
    await app(scope, receive, sender)
  File "/Users/alekenov/Library/Python/3.9/lib/python/site-packages/starlette/routing.py", line 72, in app
    response = await func(request)
  File "/Users/alekenov/Library/Python/3.9/lib/python/site-packages/fastapi/routing.py", line 299, in app
    raise e
  File "/Users/alekenov/Library/Python/3.9/lib/python/site-packages/fastapi/routing.py", line 294, in app
    raw_response = await run_endpoint_function(
  File "/Users/alekenov/Library/Python/3.9/lib/python/site-packages/fastapi/routing.py", line 193, in run_endpoint_function
    return await run_in_threadpool(dependant.call, **values)
  File "/Users/alekenov/Library/Python/3.9/lib/python/site-packages/starlette/concurrency.py", line 40, in run_in_threadpool
    return await anyio.to_thread.run_sync(func, *args)
  File "/Users/alekenov/Library/Python/3.9/lib/python/site-packages/anyio/to_thread.py", line 33, in run_sync
    return await get_asynclib().run_sync_in_worker_thread(
  File "/Users/alekenov/Library/Python/3.9/lib/python/site-packages/anyio/_backends/_asyncio.py", line 877, in run_sync_in_worker_thread
    return await future
  File "/Users/alekenov/Library/Python/3.9/lib/python/site-packages/anyio/_backends/_asyncio.py", line 807, in run
    result = context.run(func, *args)
  File "/Users/alekenov/projects/shadcn-test/backend/app/api/endpoints/orders.py", line 72, in get_orders
    'tracking_token': order.tracking_token,
AttributeError: 'Order' object has no attribute 'payment_method'
INFO:     127.0.0.1:49219 - "GET /api/orders/?limit=2 HTTP/1.1" 403 Forbidden
