INFO:     Will watch for changes in these directories: ['/Users/alekenov/projects/shadcn-test/backend']
INFO:     Uvicorn running on http://127.0.0.1:8000 (Press CTRL+C to quit)
INFO:     Started reloader process [92808] using WatchFiles
/Users/alekenov/projects/shadcn-test/backend/venv/lib/python3.9/site-packages/pydantic/_internal/_config.py:321: UserWarning: Valid config keys have changed in V2:
* 'orm_mode' has been renamed to 'from_attributes'
  warnings.warn(message, UserWarning)
INFO:     Started server process [92825]
INFO:     Waiting for application startup.
INFO:app.main:Starting Cvety.kz API
INFO:app.main:PORT: 8000
INFO:app.main:Environment: development
INFO:app.main:DATABASE_URL from env: NOT SET...
INFO:app.main:DATABASE_URL from settings: sqlite:///./flower_shop.db...
INFO:app.main:Connecting to database: Invalid DATABASE_URL format (length: 26)
INFO:app.db.session:Database engine created successfully: sqlite:///./flower_shop.db...
INFO:app.main:Database tables created successfully
INFO:app.main:Database connection test: OK
INFO:app.services.telegram_service:Telegram bot initialized: @lekenbot
INFO:app.main:Telegram bot polling started
INFO:app.main:Application startup complete
INFO:     Application startup complete.
INFO:app.services.telegram_service:Webhook removed
INFO:app.services.telegram_service:Starting Telegram bot polling...
INFO:aiogram.dispatcher:Start polling
INFO:aiogram.dispatcher:Run polling for bot @lekenbot id=823344503 - 'Доставка цветов по Казахстану'
ERROR:aiogram.dispatcher:Failed to fetch updates - TelegramConflictError: Telegram server says - Conflict: terminated by other getUpdates request; make sure that only one bot instance is running
WARNING:aiogram.dispatcher:Sleep for 1.000000 seconds and try again... (tryings = 0, bot id = 823344503)
WARNING:app.services.redis_service:REDIS_URL not found, Redis features will be disabled
INFO:app.services.otp_service:OTP generated for phone: +77011234567
INFO:     127.0.0.1:50095 - "POST /api/auth/request-otp HTTP/1.1" 201 Created
ERROR:aiogram.dispatcher:Failed to fetch updates - TelegramConflictError: Telegram server says - Conflict: terminated by other getUpdates request; make sure that only one bot instance is running
WARNING:aiogram.dispatcher:Sleep for 1.156894 seconds and try again... (tryings = 1, bot id = 823344503)
INFO:     127.0.0.1:50121 - "POST /api/auth/verify-otp HTTP/1.1" 200 OK
ERROR:aiogram.dispatcher:Failed to fetch updates - TelegramConflictError: Telegram server says - Conflict: terminated by other getUpdates request; make sure that only one bot instance is running
WARNING:aiogram.dispatcher:Sleep for 1.385495 seconds and try again... (tryings = 2, bot id = 823344503)
INFO:     127.0.0.1:50148 - "GET /api/orders/ HTTP/1.1" 200 OK
ERROR:aiogram.dispatcher:Failed to fetch updates - TelegramConflictError: Telegram server says - Conflict: terminated by other getUpdates request; make sure that only one bot instance is running
WARNING:aiogram.dispatcher:Sleep for 1.882848 seconds and try again... (tryings = 3, bot id = 823344503)
INFO:     127.0.0.1:50175 - "GET /api/orders/ HTTP/1.1" 200 OK
ERROR:aiogram.dispatcher:Failed to fetch updates - TelegramConflictError: Telegram server says - Conflict: terminated by other getUpdates request; make sure that only one bot instance is running
WARNING:aiogram.dispatcher:Sleep for 2.302035 seconds and try again... (tryings = 4, bot id = 823344503)
Order 10 has 1 items
  - Item: 21, product_name: Солнечный день, product: <app.models.product.Product object at 0x10cd26c40>
INFO:     127.0.0.1:50204 - "GET /api/orders/10 HTTP/1.1" 200 OK
INFO:     127.0.0.1:50228 - "GET /api/warehouse/ HTTP/1.1" 200 OK
ERROR:aiogram.dispatcher:Failed to fetch updates - TelegramConflictError: Telegram server says - Conflict: terminated by other getUpdates request; make sure that only one bot instance is running
WARNING:aiogram.dispatcher:Sleep for 3.035003 seconds and try again... (tryings = 5, bot id = 823344503)
ERROR:aiogram.dispatcher:Failed to fetch updates - TelegramConflictError: Telegram server says - Conflict: terminated by other getUpdates request; make sure that only one bot instance is running
WARNING:aiogram.dispatcher:Sleep for 3.834412 seconds and try again... (tryings = 6, bot id = 823344503)
ERROR:aiogram.dispatcher:Failed to fetch updates - TelegramConflictError: Telegram server says - Conflict: terminated by other getUpdates request; make sure that only one bot instance is running
WARNING:aiogram.dispatcher:Sleep for 4.910366 seconds and try again... (tryings = 7, bot id = 823344503)
INFO:app.services.otp_service:OTP generated for phone: +77011234567
INFO:     127.0.0.1:50305 - "POST /api/auth/request-otp HTTP/1.1" 201 Created
ERROR:aiogram.dispatcher:Failed to fetch updates - TelegramConflictError: Telegram server says - Conflict: terminated by other getUpdates request; make sure that only one bot instance is running
WARNING:aiogram.dispatcher:Sleep for 5.070373 seconds and try again... (tryings = 8, bot id = 823344503)
INFO:     127.0.0.1:50348 - "POST /api/auth/verify-otp HTTP/1.1" 200 OK
INFO:     127.0.0.1:50351 - "GET /api/auth/me HTTP/1.1" 200 OK
INFO:     127.0.0.1:50354 - "GET /api/auth/me HTTP/1.1" 200 OK
INFO:     127.0.0.1:50357 - "GET /api/orders/?page=1&limit=20 HTTP/1.1" 200 OK
INFO:     127.0.0.1:50385 - "GET /api/auth/me HTTP/1.1" 200 OK
INFO:     127.0.0.1:50384 - "GET /api/orders/?page=1&limit=20 HTTP/1.1" 200 OK
INFO:     127.0.0.1:50387 - "GET /api/auth/me HTTP/1.1" 200 OK
ERROR:aiogram.dispatcher:Failed to fetch updates - TelegramConflictError: Telegram server says - Conflict: terminated by other getUpdates request; make sure that only one bot instance is running
WARNING:aiogram.dispatcher:Sleep for 4.831250 seconds and try again... (tryings = 9, bot id = 823344503)
INFO:     127.0.0.1:50395 - "GET /api/auth/me HTTP/1.1" 200 OK
INFO:     127.0.0.1:50394 - "GET /api/orders/?page=1&limit=20 HTTP/1.1" 200 OK
INFO:     127.0.0.1:50397 - "GET /api/auth/me HTTP/1.1" 200 OK
ERROR:aiogram.dispatcher:Failed to fetch updates - TelegramConflictError: Telegram server says - Conflict: terminated by other getUpdates request; make sure that only one bot instance is running
WARNING:aiogram.dispatcher:Sleep for 5.022850 seconds and try again... (tryings = 10, bot id = 823344503)
ERROR:aiogram.dispatcher:Failed to fetch updates - TelegramConflictError: Telegram server says - Conflict: terminated by other getUpdates request; make sure that only one bot instance is running
WARNING:aiogram.dispatcher:Sleep for 5.319722 seconds and try again... (tryings = 11, bot id = 823344503)
ERROR:aiogram.dispatcher:Failed to fetch updates - TelegramConflictError: Telegram server says - Conflict: terminated by other getUpdates request; make sure that only one bot instance is running
WARNING:aiogram.dispatcher:Sleep for 4.902363 seconds and try again... (tryings = 12, bot id = 823344503)
INFO:     127.0.0.1:50473 - "GET /api/auth/me HTTP/1.1" 200 OK
INFO:     127.0.0.1:50475 - "GET /api/auth/me HTTP/1.1" 200 OK
INFO:     127.0.0.1:50471 - "GET /api/warehouse/?page=1&limit=20 HTTP/1.1" 200 OK
ERROR:aiogram.dispatcher:Failed to fetch updates - TelegramConflictError: Telegram server says - Conflict: terminated by other getUpdates request; make sure that only one bot instance is running
WARNING:aiogram.dispatcher:Sleep for 5.108756 seconds and try again... (tryings = 13, bot id = 823344503)
ERROR:aiogram.dispatcher:Failed to fetch updates - TelegramConflictError: Telegram server says - Conflict: terminated by other getUpdates request; make sure that only one bot instance is running
WARNING:aiogram.dispatcher:Sleep for 4.979028 seconds and try again... (tryings = 14, bot id = 823344503)
INFO:     127.0.0.1:50482 - "GET /api/orders/?page=1&limit=20 HTTP/1.1" 200 OK
INFO:     127.0.0.1:50493 - "GET /api/auth/me HTTP/1.1" 200 OK
INFO:     127.0.0.1:50495 - "GET /api/auth/me HTTP/1.1" 200 OK
INFO:     127.0.0.1:50492 - "GET /api/orders/?page=1&limit=20 HTTP/1.1" 200 OK
ERROR:aiogram.dispatcher:Failed to fetch updates - TelegramConflictError: Telegram server says - Conflict: terminated by other getUpdates request; make sure that only one bot instance is running
WARNING:aiogram.dispatcher:Sleep for 5.119385 seconds and try again... (tryings = 15, bot id = 823344503)
ERROR:aiogram.dispatcher:Failed to fetch updates - TelegramConflictError: Telegram server says - Conflict: terminated by other getUpdates request; make sure that only one bot instance is running
WARNING:aiogram.dispatcher:Sleep for 4.934971 seconds and try again... (tryings = 16, bot id = 823344503)
INFO:     127.0.0.1:50572 - "GET /api/auth/me HTTP/1.1" 200 OK
INFO:     127.0.0.1:50576 - "GET /api/auth/me HTTP/1.1" 200 OK
INFO:     127.0.0.1:50573 - "GET /api/orders/?page=1&limit=20 HTTP/1.1" 200 OK
INFO:     127.0.0.1:50579 - "GET /api/warehouse/?page=1&limit=20 HTTP/1.1" 200 OK
INFO:     127.0.0.1:50582 - "GET /api/customers/?limit=20&skip=0 HTTP/1.1" 200 OK
INFO:     127.0.0.1:50612 - "GET /api/warehouse/?page=1&limit=20 HTTP/1.1" 200 OK
ERROR:aiogram.dispatcher:Failed to fetch updates - TelegramConflictError: Telegram server says - Conflict: terminated by other getUpdates request; make sure that only one bot instance is running
WARNING:aiogram.dispatcher:Sleep for 4.923649 seconds and try again... (tryings = 17, bot id = 823344503)
INFO:     127.0.0.1:50639 - "GET /api/orders/?page=1&limit=20 HTTP/1.1" 200 OK
Order 10 has 1 items
  - Item: 21, product_name: Солнечный день, product: <app.models.product.Product object at 0x11a023e20>
INFO:     127.0.0.1:50641 - "GET /api/orders/10 HTTP/1.1" 200 OK
INFO:     127.0.0.1:50654 - "GET /api/auth/me HTTP/1.1" 200 OK
INFO:     127.0.0.1:50652 - "GET /api/orders/?page=1&limit=20 HTTP/1.1" 200 OK
INFO:     127.0.0.1:50656 - "GET /api/auth/me HTTP/1.1" 200 OK
INFO:     127.0.0.1:50679 - "GET /api/customers/?limit=20&skip=0 HTTP/1.1" 200 OK
ERROR:aiogram.dispatcher:Failed to fetch updates - TelegramConflictError: Telegram server says - Conflict: terminated by other getUpdates request; make sure that only one bot instance is running
WARNING:aiogram.dispatcher:Sleep for 5.101479 seconds and try again... (tryings = 18, bot id = 823344503)
INFO:     127.0.0.1:50707 - "GET /api/orders/?page=1&limit=20 HTTP/1.1" 200 OK
INFO:     127.0.0.1:50718 - "GET /api/auth/me HTTP/1.1" 200 OK
INFO:     127.0.0.1:50717 - "GET /api/orders/?page=1&limit=20 HTTP/1.1" 200 OK
INFO:     127.0.0.1:50720 - "GET /api/auth/me HTTP/1.1" 200 OK
ERROR:aiogram.dispatcher:Failed to fetch updates - TelegramConflictError: Telegram server says - Conflict: terminated by other getUpdates request; make sure that only one bot instance is running
WARNING:aiogram.dispatcher:Sleep for 4.906775 seconds and try again... (tryings = 19, bot id = 823344503)
INFO:     127.0.0.1:50725 - "GET /api/orders/?status=new&page=1&limit=20 HTTP/1.1" 200 OK
INFO:     127.0.0.1:50750 - "GET /api/auth/me HTTP/1.1" 200 OK
INFO:     127.0.0.1:50752 - "GET /api/auth/me HTTP/1.1" 200 OK
INFO:     127.0.0.1:50748 - "GET /api/orders/?page=1&limit=20 HTTP/1.1" 200 OK
ERROR:aiogram.dispatcher:Failed to fetch updates - TelegramConflictError: Telegram server says - Conflict: terminated by other getUpdates request; make sure that only one bot instance is running
WARNING:aiogram.dispatcher:Sleep for 5.065374 seconds and try again... (tryings = 20, bot id = 823344503)
ERROR:aiogram.dispatcher:Failed to fetch updates - TelegramConflictError: Telegram server says - Conflict: terminated by other getUpdates request; make sure that only one bot instance is running
WARNING:aiogram.dispatcher:Sleep for 5.040704 seconds and try again... (tryings = 21, bot id = 823344503)
ERROR:aiogram.dispatcher:Failed to fetch updates - TelegramConflictError: Telegram server says - Conflict: terminated by other getUpdates request; make sure that only one bot instance is running
WARNING:aiogram.dispatcher:Sleep for 4.915236 seconds and try again... (tryings = 22, bot id = 823344503)
ERROR:aiogram.dispatcher:Failed to fetch updates - TelegramConflictError: Telegram server says - Conflict: terminated by other getUpdates request; make sure that only one bot instance is running
WARNING:aiogram.dispatcher:Sleep for 5.141914 seconds and try again... (tryings = 23, bot id = 823344503)
ERROR:aiogram.dispatcher:Failed to fetch updates - TelegramConflictError: Telegram server says - Conflict: terminated by other getUpdates request; make sure that only one bot instance is running
WARNING:aiogram.dispatcher:Sleep for 5.216096 seconds and try again... (tryings = 24, bot id = 823344503)
ERROR:aiogram.dispatcher:Failed to fetch updates - TelegramConflictError: Telegram server says - Conflict: terminated by other getUpdates request; make sure that only one bot instance is running
WARNING:aiogram.dispatcher:Sleep for 5.202512 seconds and try again... (tryings = 25, bot id = 823344503)
ERROR:aiogram.dispatcher:Failed to fetch updates - TelegramConflictError: Telegram server says - Conflict: terminated by other getUpdates request; make sure that only one bot instance is running
WARNING:aiogram.dispatcher:Sleep for 4.945930 seconds and try again... (tryings = 26, bot id = 823344503)
ERROR:aiogram.dispatcher:Failed to fetch updates - TelegramConflictError: Telegram server says - Conflict: terminated by other getUpdates request; make sure that only one bot instance is running
WARNING:aiogram.dispatcher:Sleep for 4.975332 seconds and try again... (tryings = 27, bot id = 823344503)
INFO:     127.0.0.1:50834 - "GET /api/customers/?limit=20&skip=0 HTTP/1.1" 200 OK
ERROR:aiogram.dispatcher:Failed to fetch updates - TelegramConflictError: Telegram server says - Conflict: terminated by other getUpdates request; make sure that only one bot instance is running
WARNING:aiogram.dispatcher:Sleep for 5.071384 seconds and try again... (tryings = 28, bot id = 823344503)
ERROR:aiogram.dispatcher:Failed to fetch updates - TelegramConflictError: Telegram server says - Conflict: terminated by other getUpdates request; make sure that only one bot instance is running
WARNING:aiogram.dispatcher:Sleep for 5.141977 seconds and try again... (tryings = 29, bot id = 823344503)
ERROR:aiogram.dispatcher:Failed to fetch updates - TelegramConflictError: Telegram server says - Conflict: terminated by other getUpdates request; make sure that only one bot instance is running
WARNING:aiogram.dispatcher:Sleep for 4.958981 seconds and try again... (tryings = 30, bot id = 823344503)
ERROR:aiogram.dispatcher:Failed to fetch updates - TelegramConflictError: Telegram server says - Conflict: terminated by other getUpdates request; make sure that only one bot instance is running
WARNING:aiogram.dispatcher:Sleep for 4.837141 seconds and try again... (tryings = 31, bot id = 823344503)
ERROR:aiogram.dispatcher:Failed to fetch updates - TelegramConflictError: Telegram server says - Conflict: terminated by other getUpdates request; make sure that only one bot instance is running
WARNING:aiogram.dispatcher:Sleep for 4.968473 seconds and try again... (tryings = 32, bot id = 823344503)
ERROR:aiogram.dispatcher:Failed to fetch updates - TelegramConflictError: Telegram server says - Conflict: terminated by other getUpdates request; make sure that only one bot instance is running
WARNING:aiogram.dispatcher:Sleep for 5.032772 seconds and try again... (tryings = 33, bot id = 823344503)
ERROR:aiogram.dispatcher:Failed to fetch updates - TelegramConflictError: Telegram server says - Conflict: terminated by other getUpdates request; make sure that only one bot instance is running
WARNING:aiogram.dispatcher:Sleep for 5.026584 seconds and try again... (tryings = 34, bot id = 823344503)
ERROR:aiogram.dispatcher:Failed to fetch updates - TelegramConflictError: Telegram server says - Conflict: terminated by other getUpdates request; make sure that only one bot instance is running
WARNING:aiogram.dispatcher:Sleep for 5.074542 seconds and try again... (tryings = 35, bot id = 823344503)
ERROR:aiogram.dispatcher:Failed to fetch updates - TelegramConflictError: Telegram server says - Conflict: terminated by other getUpdates request; make sure that only one bot instance is running
WARNING:aiogram.dispatcher:Sleep for 5.044927 seconds and try again... (tryings = 36, bot id = 823344503)
ERROR:aiogram.dispatcher:Failed to fetch updates - TelegramConflictError: Telegram server says - Conflict: terminated by other getUpdates request; make sure that only one bot instance is running
WARNING:aiogram.dispatcher:Sleep for 5.033653 seconds and try again... (tryings = 37, bot id = 823344503)
ERROR:aiogram.dispatcher:Failed to fetch updates - TelegramConflictError: Telegram server says - Conflict: terminated by other getUpdates request; make sure that only one bot instance is running
WARNING:aiogram.dispatcher:Sleep for 4.960557 seconds and try again... (tryings = 38, bot id = 823344503)
ERROR:aiogram.dispatcher:Failed to fetch updates - TelegramConflictError: Telegram server says - Conflict: terminated by other getUpdates request; make sure that only one bot instance is running
WARNING:aiogram.dispatcher:Sleep for 4.949786 seconds and try again... (tryings = 39, bot id = 823344503)
ERROR:aiogram.dispatcher:Failed to fetch updates - TelegramConflictError: Telegram server says - Conflict: terminated by other getUpdates request; make sure that only one bot instance is running
WARNING:aiogram.dispatcher:Sleep for 5.158582 seconds and try again... (tryings = 40, bot id = 823344503)
WARNING:  WatchFiles detected changes in 'seed_data.py'. Reloading...
WARNING:aiogram.dispatcher:Received SIGTERM signal
INFO:aiogram.dispatcher:Polling stopped for bot @lekenbot id=823344503 - 'Доставка цветов по Казахстану'
INFO:aiogram.dispatcher:Polling stopped
INFO:     127.0.0.1:51039 - "GET /api/auth/me HTTP/1.1" 200 OK
INFO:     127.0.0.1:51041 - "GET /api/auth/me HTTP/1.1" 200 OK
INFO:     127.0.0.1:51037 - "GET /api/customers/?limit=20&skip=0 HTTP/1.1" 200 OK
INFO:     127.0.0.1:51078 - "GET /api/auth/me HTTP/1.1" 200 OK
INFO:     127.0.0.1:51080 - "GET /api/auth/me HTTP/1.1" 200 OK
INFO:     127.0.0.1:51077 - "GET /api/customers/?limit=20&skip=0 HTTP/1.1" 200 OK
INFO:     127.0.0.1:51132 - "GET /api/customers/?limit=5 HTTP/1.1" 401 Unauthorized
INFO:     127.0.0.1:51166 - "GET /api/auth/me HTTP/1.1" 200 OK
INFO:     127.0.0.1:51168 - "GET /api/auth/me HTTP/1.1" 200 OK
INFO:     127.0.0.1:51165 - "GET /api/customers/?limit=20&skip=0 HTTP/1.1" 200 OK
INFO:app.services.otp_service:OTP generated for phone: +77011234567
INFO:     127.0.0.1:51171 - "POST /api/auth/request-otp HTTP/1.1" 201 Created
INFO:     127.0.0.1:51196 - "POST /api/auth/verify-otp HTTP/1.1" 422 Unprocessable Entity
INFO:     127.0.0.1:51198 - "POST /api/auth/verify-otp HTTP/1.1" 200 OK
INFO:     127.0.0.1:51202 - "GET /api/customers/?limit=5 HTTP/1.1" 200 OK
INFO:app.services.otp_service:OTP generated for phone: +77011234567
INFO:     127.0.0.1:51269 - "POST /api/auth/request-otp HTTP/1.1" 201 Created
INFO:     127.0.0.1:51292 - "POST /api/auth/verify-otp HTTP/1.1" 200 OK
INFO:     127.0.0.1:51298 - "GET /api/auth/me HTTP/1.1" 200 OK
INFO:     127.0.0.1:51301 - "GET /api/auth/me HTTP/1.1" 200 OK
INFO:     127.0.0.1:51296 - "GET /api/customers/?limit=20&skip=0 HTTP/1.1" 200 OK
INFO:     127.0.0.1:51345 - "GET /api/warehouse/?page=1&limit=20 HTTP/1.1" 200 OK
INFO:     127.0.0.1:51350 - "GET /api/orders/?page=1&limit=20 HTTP/1.1" 200 OK
INFO:     127.0.0.1:51353 - "GET /api/products/ HTTP/1.1" 500 Internal Server Error
ERROR:    Exception in ASGI application
Traceback (most recent call last):
  File "/Users/alekenov/projects/shadcn-test/backend/venv/lib/python3.9/site-packages/uvicorn/protocols/http/httptools_impl.py", line 426, in run_asgi
    result = await app(  # type: ignore[func-returns-value]
  File "/Users/alekenov/projects/shadcn-test/backend/venv/lib/python3.9/site-packages/uvicorn/middleware/proxy_headers.py", line 84, in __call__
    return await self.app(scope, receive, send)
  File "/Users/alekenov/projects/shadcn-test/backend/venv/lib/python3.9/site-packages/fastapi/applications.py", line 1054, in __call__
    await super().__call__(scope, receive, send)
  File "/Users/alekenov/projects/shadcn-test/backend/venv/lib/python3.9/site-packages/starlette/applications.py", line 123, in __call__
    await self.middleware_stack(scope, receive, send)
  File "/Users/alekenov/projects/shadcn-test/backend/venv/lib/python3.9/site-packages/starlette/middleware/errors.py", line 186, in __call__
    raise exc
  File "/Users/alekenov/projects/shadcn-test/backend/venv/lib/python3.9/site-packages/starlette/middleware/errors.py", line 164, in __call__
    await self.app(scope, receive, _send)
  File "/Users/alekenov/projects/shadcn-test/backend/venv/lib/python3.9/site-packages/starlette/middleware/cors.py", line 83, in __call__
    await self.app(scope, receive, send)
  File "/Users/alekenov/projects/shadcn-test/backend/venv/lib/python3.9/site-packages/starlette/middleware/exceptions.py", line 62, in __call__
    await wrap_app_handling_exceptions(self.app, conn)(scope, receive, send)
  File "/Users/alekenov/projects/shadcn-test/backend/venv/lib/python3.9/site-packages/starlette/_exception_handler.py", line 64, in wrapped_app
    raise exc
  File "/Users/alekenov/projects/shadcn-test/backend/venv/lib/python3.9/site-packages/starlette/_exception_handler.py", line 53, in wrapped_app
    await app(scope, receive, sender)
  File "/Users/alekenov/projects/shadcn-test/backend/venv/lib/python3.9/site-packages/starlette/routing.py", line 762, in __call__
    await self.middleware_stack(scope, receive, send)
  File "/Users/alekenov/projects/shadcn-test/backend/venv/lib/python3.9/site-packages/starlette/routing.py", line 782, in app
    await route.handle(scope, receive, send)
  File "/Users/alekenov/projects/shadcn-test/backend/venv/lib/python3.9/site-packages/starlette/routing.py", line 297, in handle
    await self.app(scope, receive, send)
  File "/Users/alekenov/projects/shadcn-test/backend/venv/lib/python3.9/site-packages/starlette/routing.py", line 77, in app
    await wrap_app_handling_exceptions(app, request)(scope, receive, send)
  File "/Users/alekenov/projects/shadcn-test/backend/venv/lib/python3.9/site-packages/starlette/_exception_handler.py", line 64, in wrapped_app
    raise exc
  File "/Users/alekenov/projects/shadcn-test/backend/venv/lib/python3.9/site-packages/starlette/_exception_handler.py", line 53, in wrapped_app
    await app(scope, receive, sender)
  File "/Users/alekenov/projects/shadcn-test/backend/venv/lib/python3.9/site-packages/starlette/routing.py", line 72, in app
    response = await func(request)
  File "/Users/alekenov/projects/shadcn-test/backend/venv/lib/python3.9/site-packages/fastapi/routing.py", line 299, in app
    raise e
  File "/Users/alekenov/projects/shadcn-test/backend/venv/lib/python3.9/site-packages/fastapi/routing.py", line 294, in app
    raw_response = await run_endpoint_function(
  File "/Users/alekenov/projects/shadcn-test/backend/venv/lib/python3.9/site-packages/fastapi/routing.py", line 193, in run_endpoint_function
    return await run_in_threadpool(dependant.call, **values)
  File "/Users/alekenov/projects/shadcn-test/backend/venv/lib/python3.9/site-packages/starlette/concurrency.py", line 40, in run_in_threadpool
    return await anyio.to_thread.run_sync(func, *args)
  File "/Users/alekenov/projects/shadcn-test/backend/venv/lib/python3.9/site-packages/anyio/to_thread.py", line 56, in run_sync
    return await get_async_backend().run_sync_in_worker_thread(
  File "/Users/alekenov/projects/shadcn-test/backend/venv/lib/python3.9/site-packages/anyio/_backends/_asyncio.py", line 2470, in run_sync_in_worker_thread
    return await future
  File "/Users/alekenov/projects/shadcn-test/backend/venv/lib/python3.9/site-packages/anyio/_backends/_asyncio.py", line 967, in run
    result = context.run(func, *args)
  File "/Users/alekenov/projects/shadcn-test/backend/app/api/endpoints/products.py", line 60, in read_products
    product_schemas = [schemas.Product.from_orm(product) for product in products]
  File "/Users/alekenov/projects/shadcn-test/backend/app/api/endpoints/products.py", line 60, in <listcomp>
    product_schemas = [schemas.Product.from_orm(product) for product in products]
  File "/Users/alekenov/projects/shadcn-test/backend/venv/lib/python3.9/site-packages/typing_extensions.py", line 2956, in wrapper
    return arg(*args, **kwargs)
  File "/Users/alekenov/projects/shadcn-test/backend/venv/lib/python3.9/site-packages/pydantic/main.py", line 1129, in from_orm
    return cls.model_validate(obj)
  File "/Users/alekenov/projects/shadcn-test/backend/venv/lib/python3.9/site-packages/pydantic/main.py", line 503, in model_validate
    return cls.__pydantic_validator__.validate_python(
pydantic_core._pydantic_core.ValidationError: 1 validation error for Product
retail_price
  Field required [type=missing, input_value=<app.models.product.Product object at 0x11a094ac0>, input_type=Product]
    For further information visit https://errors.pydantic.dev/2.5/v/missing
INFO:     127.0.0.1:51356 - "GET /api/products/ HTTP/1.1" 500 Internal Server Error
ERROR:    Exception in ASGI application
Traceback (most recent call last):
  File "/Users/alekenov/projects/shadcn-test/backend/venv/lib/python3.9/site-packages/uvicorn/protocols/http/httptools_impl.py", line 426, in run_asgi
    result = await app(  # type: ignore[func-returns-value]
  File "/Users/alekenov/projects/shadcn-test/backend/venv/lib/python3.9/site-packages/uvicorn/middleware/proxy_headers.py", line 84, in __call__
    return await self.app(scope, receive, send)
  File "/Users/alekenov/projects/shadcn-test/backend/venv/lib/python3.9/site-packages/fastapi/applications.py", line 1054, in __call__
    await super().__call__(scope, receive, send)
  File "/Users/alekenov/projects/shadcn-test/backend/venv/lib/python3.9/site-packages/starlette/applications.py", line 123, in __call__
    await self.middleware_stack(scope, receive, send)
  File "/Users/alekenov/projects/shadcn-test/backend/venv/lib/python3.9/site-packages/starlette/middleware/errors.py", line 186, in __call__
    raise exc
  File "/Users/alekenov/projects/shadcn-test/backend/venv/lib/python3.9/site-packages/starlette/middleware/errors.py", line 164, in __call__
    await self.app(scope, receive, _send)
  File "/Users/alekenov/projects/shadcn-test/backend/venv/lib/python3.9/site-packages/starlette/middleware/cors.py", line 83, in __call__
    await self.app(scope, receive, send)
  File "/Users/alekenov/projects/shadcn-test/backend/venv/lib/python3.9/site-packages/starlette/middleware/exceptions.py", line 62, in __call__
    await wrap_app_handling_exceptions(self.app, conn)(scope, receive, send)
  File "/Users/alekenov/projects/shadcn-test/backend/venv/lib/python3.9/site-packages/starlette/_exception_handler.py", line 64, in wrapped_app
    raise exc
  File "/Users/alekenov/projects/shadcn-test/backend/venv/lib/python3.9/site-packages/starlette/_exception_handler.py", line 53, in wrapped_app
    await app(scope, receive, sender)
  File "/Users/alekenov/projects/shadcn-test/backend/venv/lib/python3.9/site-packages/starlette/routing.py", line 762, in __call__
    await self.middleware_stack(scope, receive, send)
  File "/Users/alekenov/projects/shadcn-test/backend/venv/lib/python3.9/site-packages/starlette/routing.py", line 782, in app
    await route.handle(scope, receive, send)
  File "/Users/alekenov/projects/shadcn-test/backend/venv/lib/python3.9/site-packages/starlette/routing.py", line 297, in handle
    await self.app(scope, receive, send)
  File "/Users/alekenov/projects/shadcn-test/backend/venv/lib/python3.9/site-packages/starlette/routing.py", line 77, in app
    await wrap_app_handling_exceptions(app, request)(scope, receive, send)
  File "/Users/alekenov/projects/shadcn-test/backend/venv/lib/python3.9/site-packages/starlette/_exception_handler.py", line 64, in wrapped_app
    raise exc
  File "/Users/alekenov/projects/shadcn-test/backend/venv/lib/python3.9/site-packages/starlette/_exception_handler.py", line 53, in wrapped_app
    await app(scope, receive, sender)
  File "/Users/alekenov/projects/shadcn-test/backend/venv/lib/python3.9/site-packages/starlette/routing.py", line 72, in app
    response = await func(request)
  File "/Users/alekenov/projects/shadcn-test/backend/venv/lib/python3.9/site-packages/fastapi/routing.py", line 299, in app
    raise e
  File "/Users/alekenov/projects/shadcn-test/backend/venv/lib/python3.9/site-packages/fastapi/routing.py", line 294, in app
    raw_response = await run_endpoint_function(
  File "/Users/alekenov/projects/shadcn-test/backend/venv/lib/python3.9/site-packages/fastapi/routing.py", line 193, in run_endpoint_function
    return await run_in_threadpool(dependant.call, **values)
  File "/Users/alekenov/projects/shadcn-test/backend/venv/lib/python3.9/site-packages/starlette/concurrency.py", line 40, in run_in_threadpool
    return await anyio.to_thread.run_sync(func, *args)
  File "/Users/alekenov/projects/shadcn-test/backend/venv/lib/python3.9/site-packages/anyio/to_thread.py", line 56, in run_sync
    return await get_async_backend().run_sync_in_worker_thread(
  File "/Users/alekenov/projects/shadcn-test/backend/venv/lib/python3.9/site-packages/anyio/_backends/_asyncio.py", line 2470, in run_sync_in_worker_thread
    return await future
  File "/Users/alekenov/projects/shadcn-test/backend/venv/lib/python3.9/site-packages/anyio/_backends/_asyncio.py", line 967, in run
    result = context.run(func, *args)
  File "/Users/alekenov/projects/shadcn-test/backend/app/api/endpoints/products.py", line 60, in read_products
    product_schemas = [schemas.Product.from_orm(product) for product in products]
  File "/Users/alekenov/projects/shadcn-test/backend/app/api/endpoints/products.py", line 60, in <listcomp>
    product_schemas = [schemas.Product.from_orm(product) for product in products]
  File "/Users/alekenov/projects/shadcn-test/backend/venv/lib/python3.9/site-packages/typing_extensions.py", line 2956, in wrapper
    return arg(*args, **kwargs)
  File "/Users/alekenov/projects/shadcn-test/backend/venv/lib/python3.9/site-packages/pydantic/main.py", line 1129, in from_orm
    return cls.model_validate(obj)
  File "/Users/alekenov/projects/shadcn-test/backend/venv/lib/python3.9/site-packages/pydantic/main.py", line 503, in model_validate
    return cls.__pydantic_validator__.validate_python(
pydantic_core._pydantic_core.ValidationError: 1 validation error for Product
retail_price
  Field required [type=missing, input_value=<app.models.product.Product object at 0x11a33ad60>, input_type=Product]
    For further information visit https://errors.pydantic.dev/2.5/v/missing
INFO:     127.0.0.1:51367 - "GET /api/auth/me HTTP/1.1" 200 OK
INFO:     127.0.0.1:51366 - "GET /api/products/ HTTP/1.1" 500 Internal Server Error
ERROR:    Exception in ASGI application
Traceback (most recent call last):
  File "/Users/alekenov/projects/shadcn-test/backend/venv/lib/python3.9/site-packages/uvicorn/protocols/http/httptools_impl.py", line 426, in run_asgi
    result = await app(  # type: ignore[func-returns-value]
  File "/Users/alekenov/projects/shadcn-test/backend/venv/lib/python3.9/site-packages/uvicorn/middleware/proxy_headers.py", line 84, in __call__
    return await self.app(scope, receive, send)
  File "/Users/alekenov/projects/shadcn-test/backend/venv/lib/python3.9/site-packages/fastapi/applications.py", line 1054, in __call__
    await super().__call__(scope, receive, send)
  File "/Users/alekenov/projects/shadcn-test/backend/venv/lib/python3.9/site-packages/starlette/applications.py", line 123, in __call__
    await self.middleware_stack(scope, receive, send)
  File "/Users/alekenov/projects/shadcn-test/backend/venv/lib/python3.9/site-packages/starlette/middleware/errors.py", line 186, in __call__
    raise exc
  File "/Users/alekenov/projects/shadcn-test/backend/venv/lib/python3.9/site-packages/starlette/middleware/errors.py", line 164, in __call__
    await self.app(scope, receive, _send)
  File "/Users/alekenov/projects/shadcn-test/backend/venv/lib/python3.9/site-packages/starlette/middleware/cors.py", line 83, in __call__
    await self.app(scope, receive, send)
  File "/Users/alekenov/projects/shadcn-test/backend/venv/lib/python3.9/site-packages/starlette/middleware/exceptions.py", line 62, in __call__
    await wrap_app_handling_exceptions(self.app, conn)(scope, receive, send)
  File "/Users/alekenov/projects/shadcn-test/backend/venv/lib/python3.9/site-packages/starlette/_exception_handler.py", line 64, in wrapped_app
    raise exc
  File "/Users/alekenov/projects/shadcn-test/backend/venv/lib/python3.9/site-packages/starlette/_exception_handler.py", line 53, in wrapped_app
    await app(scope, receive, sender)
  File "/Users/alekenov/projects/shadcn-test/backend/venv/lib/python3.9/site-packages/starlette/routing.py", line 762, in __call__
    await self.middleware_stack(scope, receive, send)
  File "/Users/alekenov/projects/shadcn-test/backend/venv/lib/python3.9/site-packages/starlette/routing.py", line 782, in app
    await route.handle(scope, receive, send)
  File "/Users/alekenov/projects/shadcn-test/backend/venv/lib/python3.9/site-packages/starlette/routing.py", line 297, in handle
    await self.app(scope, receive, send)
  File "/Users/alekenov/projects/shadcn-test/backend/venv/lib/python3.9/site-packages/starlette/routing.py", line 77, in app
    await wrap_app_handling_exceptions(app, request)(scope, receive, send)
  File "/Users/alekenov/projects/shadcn-test/backend/venv/lib/python3.9/site-packages/starlette/_exception_handler.py", line 64, in wrapped_app
    raise exc
  File "/Users/alekenov/projects/shadcn-test/backend/venv/lib/python3.9/site-packages/starlette/_exception_handler.py", line 53, in wrapped_app
    await app(scope, receive, sender)
  File "/Users/alekenov/projects/shadcn-test/backend/venv/lib/python3.9/site-packages/starlette/routing.py", line 72, in app
    response = await func(request)
  File "/Users/alekenov/projects/shadcn-test/backend/venv/lib/python3.9/site-packages/fastapi/routing.py", line 299, in app
    raise e
  File "/Users/alekenov/projects/shadcn-test/backend/venv/lib/python3.9/site-packages/fastapi/routing.py", line 294, in app
    raw_response = await run_endpoint_function(
  File "/Users/alekenov/projects/shadcn-test/backend/venv/lib/python3.9/site-packages/fastapi/routing.py", line 193, in run_endpoint_function
    return await run_in_threadpool(dependant.call, **values)
  File "/Users/alekenov/projects/shadcn-test/backend/venv/lib/python3.9/site-packages/starlette/concurrency.py", line 40, in run_in_threadpool
    return await anyio.to_thread.run_sync(func, *args)
  File "/Users/alekenov/projects/shadcn-test/backend/venv/lib/python3.9/site-packages/anyio/to_thread.py", line 56, in run_sync
    return await get_async_backend().run_sync_in_worker_thread(
  File "/Users/alekenov/projects/shadcn-test/backend/venv/lib/python3.9/site-packages/anyio/_backends/_asyncio.py", line 2470, in run_sync_in_worker_thread
    return await future
  File "/Users/alekenov/projects/shadcn-test/backend/venv/lib/python3.9/site-packages/anyio/_backends/_asyncio.py", line 967, in run
    result = context.run(func, *args)
  File "/Users/alekenov/projects/shadcn-test/backend/app/api/endpoints/products.py", line 60, in read_products
    product_schemas = [schemas.Product.from_orm(product) for product in products]
  File "/Users/alekenov/projects/shadcn-test/backend/app/api/endpoints/products.py", line 60, in <listcomp>
    product_schemas = [schemas.Product.from_orm(product) for product in products]
  File "/Users/alekenov/projects/shadcn-test/backend/venv/lib/python3.9/site-packages/typing_extensions.py", line 2956, in wrapper
    return arg(*args, **kwargs)
  File "/Users/alekenov/projects/shadcn-test/backend/venv/lib/python3.9/site-packages/pydantic/main.py", line 1129, in from_orm
    return cls.model_validate(obj)
  File "/Users/alekenov/projects/shadcn-test/backend/venv/lib/python3.9/site-packages/pydantic/main.py", line 503, in model_validate
    return cls.__pydantic_validator__.validate_python(
pydantic_core._pydantic_core.ValidationError: 1 validation error for Product
retail_price
  Field required [type=missing, input_value=<app.models.product.Product object at 0x11a33acd0>, input_type=Product]
    For further information visit https://errors.pydantic.dev/2.5/v/missing
INFO:     127.0.0.1:51369 - "GET /api/auth/me HTTP/1.1" 200 OK
INFO:     127.0.0.1:51371 - "GET /api/products/ HTTP/1.1" 500 Internal Server Error
ERROR:    Exception in ASGI application
Traceback (most recent call last):
  File "/Users/alekenov/projects/shadcn-test/backend/venv/lib/python3.9/site-packages/uvicorn/protocols/http/httptools_impl.py", line 426, in run_asgi
    result = await app(  # type: ignore[func-returns-value]
  File "/Users/alekenov/projects/shadcn-test/backend/venv/lib/python3.9/site-packages/uvicorn/middleware/proxy_headers.py", line 84, in __call__
    return await self.app(scope, receive, send)
  File "/Users/alekenov/projects/shadcn-test/backend/venv/lib/python3.9/site-packages/fastapi/applications.py", line 1054, in __call__
    await super().__call__(scope, receive, send)
  File "/Users/alekenov/projects/shadcn-test/backend/venv/lib/python3.9/site-packages/starlette/applications.py", line 123, in __call__
    await self.middleware_stack(scope, receive, send)
  File "/Users/alekenov/projects/shadcn-test/backend/venv/lib/python3.9/site-packages/starlette/middleware/errors.py", line 186, in __call__
    raise exc
  File "/Users/alekenov/projects/shadcn-test/backend/venv/lib/python3.9/site-packages/starlette/middleware/errors.py", line 164, in __call__
    await self.app(scope, receive, _send)
  File "/Users/alekenov/projects/shadcn-test/backend/venv/lib/python3.9/site-packages/starlette/middleware/cors.py", line 83, in __call__
    await self.app(scope, receive, send)
  File "/Users/alekenov/projects/shadcn-test/backend/venv/lib/python3.9/site-packages/starlette/middleware/exceptions.py", line 62, in __call__
    await wrap_app_handling_exceptions(self.app, conn)(scope, receive, send)
  File "/Users/alekenov/projects/shadcn-test/backend/venv/lib/python3.9/site-packages/starlette/_exception_handler.py", line 64, in wrapped_app
    raise exc
  File "/Users/alekenov/projects/shadcn-test/backend/venv/lib/python3.9/site-packages/starlette/_exception_handler.py", line 53, in wrapped_app
    await app(scope, receive, sender)
  File "/Users/alekenov/projects/shadcn-test/backend/venv/lib/python3.9/site-packages/starlette/routing.py", line 762, in __call__
    await self.middleware_stack(scope, receive, send)
  File "/Users/alekenov/projects/shadcn-test/backend/venv/lib/python3.9/site-packages/starlette/routing.py", line 782, in app
    await route.handle(scope, receive, send)
  File "/Users/alekenov/projects/shadcn-test/backend/venv/lib/python3.9/site-packages/starlette/routing.py", line 297, in handle
    await self.app(scope, receive, send)
  File "/Users/alekenov/projects/shadcn-test/backend/venv/lib/python3.9/site-packages/starlette/routing.py", line 77, in app
    await wrap_app_handling_exceptions(app, request)(scope, receive, send)
  File "/Users/alekenov/projects/shadcn-test/backend/venv/lib/python3.9/site-packages/starlette/_exception_handler.py", line 64, in wrapped_app
    raise exc
  File "/Users/alekenov/projects/shadcn-test/backend/venv/lib/python3.9/site-packages/starlette/_exception_handler.py", line 53, in wrapped_app
    await app(scope, receive, sender)
  File "/Users/alekenov/projects/shadcn-test/backend/venv/lib/python3.9/site-packages/starlette/routing.py", line 72, in app
    response = await func(request)
  File "/Users/alekenov/projects/shadcn-test/backend/venv/lib/python3.9/site-packages/fastapi/routing.py", line 299, in app
    raise e
  File "/Users/alekenov/projects/shadcn-test/backend/venv/lib/python3.9/site-packages/fastapi/routing.py", line 294, in app
    raw_response = await run_endpoint_function(
  File "/Users/alekenov/projects/shadcn-test/backend/venv/lib/python3.9/site-packages/fastapi/routing.py", line 193, in run_endpoint_function
    return await run_in_threadpool(dependant.call, **values)
  File "/Users/alekenov/projects/shadcn-test/backend/venv/lib/python3.9/site-packages/starlette/concurrency.py", line 40, in run_in_threadpool
    return await anyio.to_thread.run_sync(func, *args)
  File "/Users/alekenov/projects/shadcn-test/backend/venv/lib/python3.9/site-packages/anyio/to_thread.py", line 56, in run_sync
    return await get_async_backend().run_sync_in_worker_thread(
  File "/Users/alekenov/projects/shadcn-test/backend/venv/lib/python3.9/site-packages/anyio/_backends/_asyncio.py", line 2470, in run_sync_in_worker_thread
    return await future
  File "/Users/alekenov/projects/shadcn-test/backend/venv/lib/python3.9/site-packages/anyio/_backends/_asyncio.py", line 967, in run
    result = context.run(func, *args)
  File "/Users/alekenov/projects/shadcn-test/backend/app/api/endpoints/products.py", line 60, in read_products
    product_schemas = [schemas.Product.from_orm(product) for product in products]
  File "/Users/alekenov/projects/shadcn-test/backend/app/api/endpoints/products.py", line 60, in <listcomp>
    product_schemas = [schemas.Product.from_orm(product) for product in products]
  File "/Users/alekenov/projects/shadcn-test/backend/venv/lib/python3.9/site-packages/typing_extensions.py", line 2956, in wrapper
    return arg(*args, **kwargs)
  File "/Users/alekenov/projects/shadcn-test/backend/venv/lib/python3.9/site-packages/pydantic/main.py", line 1129, in from_orm
    return cls.model_validate(obj)
  File "/Users/alekenov/projects/shadcn-test/backend/venv/lib/python3.9/site-packages/pydantic/main.py", line 503, in model_validate
    return cls.__pydantic_validator__.validate_python(
pydantic_core._pydantic_core.ValidationError: 1 validation error for Product
retail_price
  Field required [type=missing, input_value=<app.models.product.Product object at 0x11a340430>, input_type=Product]
    For further information visit https://errors.pydantic.dev/2.5/v/missing
INFO:     127.0.0.1:51373 - "GET /api/products/ HTTP/1.1" 500 Internal Server Error
ERROR:    Exception in ASGI application
Traceback (most recent call last):
  File "/Users/alekenov/projects/shadcn-test/backend/venv/lib/python3.9/site-packages/uvicorn/protocols/http/httptools_impl.py", line 426, in run_asgi
    result = await app(  # type: ignore[func-returns-value]
  File "/Users/alekenov/projects/shadcn-test/backend/venv/lib/python3.9/site-packages/uvicorn/middleware/proxy_headers.py", line 84, in __call__
    return await self.app(scope, receive, send)
  File "/Users/alekenov/projects/shadcn-test/backend/venv/lib/python3.9/site-packages/fastapi/applications.py", line 1054, in __call__
    await super().__call__(scope, receive, send)
  File "/Users/alekenov/projects/shadcn-test/backend/venv/lib/python3.9/site-packages/starlette/applications.py", line 123, in __call__
    await self.middleware_stack(scope, receive, send)
  File "/Users/alekenov/projects/shadcn-test/backend/venv/lib/python3.9/site-packages/starlette/middleware/errors.py", line 186, in __call__
    raise exc
  File "/Users/alekenov/projects/shadcn-test/backend/venv/lib/python3.9/site-packages/starlette/middleware/errors.py", line 164, in __call__
    await self.app(scope, receive, _send)
  File "/Users/alekenov/projects/shadcn-test/backend/venv/lib/python3.9/site-packages/starlette/middleware/cors.py", line 83, in __call__
    await self.app(scope, receive, send)
  File "/Users/alekenov/projects/shadcn-test/backend/venv/lib/python3.9/site-packages/starlette/middleware/exceptions.py", line 62, in __call__
    await wrap_app_handling_exceptions(self.app, conn)(scope, receive, send)
  File "/Users/alekenov/projects/shadcn-test/backend/venv/lib/python3.9/site-packages/starlette/_exception_handler.py", line 64, in wrapped_app
    raise exc
  File "/Users/alekenov/projects/shadcn-test/backend/venv/lib/python3.9/site-packages/starlette/_exception_handler.py", line 53, in wrapped_app
    await app(scope, receive, sender)
  File "/Users/alekenov/projects/shadcn-test/backend/venv/lib/python3.9/site-packages/starlette/routing.py", line 762, in __call__
    await self.middleware_stack(scope, receive, send)
  File "/Users/alekenov/projects/shadcn-test/backend/venv/lib/python3.9/site-packages/starlette/routing.py", line 782, in app
    await route.handle(scope, receive, send)
  File "/Users/alekenov/projects/shadcn-test/backend/venv/lib/python3.9/site-packages/starlette/routing.py", line 297, in handle
    await self.app(scope, receive, send)
  File "/Users/alekenov/projects/shadcn-test/backend/venv/lib/python3.9/site-packages/starlette/routing.py", line 77, in app
    await wrap_app_handling_exceptions(app, request)(scope, receive, send)
  File "/Users/alekenov/projects/shadcn-test/backend/venv/lib/python3.9/site-packages/starlette/_exception_handler.py", line 64, in wrapped_app
    raise exc
  File "/Users/alekenov/projects/shadcn-test/backend/venv/lib/python3.9/site-packages/starlette/_exception_handler.py", line 53, in wrapped_app
    await app(scope, receive, sender)
  File "/Users/alekenov/projects/shadcn-test/backend/venv/lib/python3.9/site-packages/starlette/routing.py", line 72, in app
    response = await func(request)
  File "/Users/alekenov/projects/shadcn-test/backend/venv/lib/python3.9/site-packages/fastapi/routing.py", line 299, in app
    raise e
  File "/Users/alekenov/projects/shadcn-test/backend/venv/lib/python3.9/site-packages/fastapi/routing.py", line 294, in app
    raw_response = await run_endpoint_function(
  File "/Users/alekenov/projects/shadcn-test/backend/venv/lib/python3.9/site-packages/fastapi/routing.py", line 193, in run_endpoint_function
    return await run_in_threadpool(dependant.call, **values)
  File "/Users/alekenov/projects/shadcn-test/backend/venv/lib/python3.9/site-packages/starlette/concurrency.py", line 40, in run_in_threadpool
    return await anyio.to_thread.run_sync(func, *args)
  File "/Users/alekenov/projects/shadcn-test/backend/venv/lib/python3.9/site-packages/anyio/to_thread.py", line 56, in run_sync
    return await get_async_backend().run_sync_in_worker_thread(
  File "/Users/alekenov/projects/shadcn-test/backend/venv/lib/python3.9/site-packages/anyio/_backends/_asyncio.py", line 2470, in run_sync_in_worker_thread
    return await future
  File "/Users/alekenov/projects/shadcn-test/backend/venv/lib/python3.9/site-packages/anyio/_backends/_asyncio.py", line 967, in run
    result = context.run(func, *args)
  File "/Users/alekenov/projects/shadcn-test/backend/app/api/endpoints/products.py", line 60, in read_products
    product_schemas = [schemas.Product.from_orm(product) for product in products]
  File "/Users/alekenov/projects/shadcn-test/backend/app/api/endpoints/products.py", line 60, in <listcomp>
    product_schemas = [schemas.Product.from_orm(product) for product in products]
  File "/Users/alekenov/projects/shadcn-test/backend/venv/lib/python3.9/site-packages/typing_extensions.py", line 2956, in wrapper
    return arg(*args, **kwargs)
  File "/Users/alekenov/projects/shadcn-test/backend/venv/lib/python3.9/site-packages/pydantic/main.py", line 1129, in from_orm
    return cls.model_validate(obj)
  File "/Users/alekenov/projects/shadcn-test/backend/venv/lib/python3.9/site-packages/pydantic/main.py", line 503, in model_validate
    return cls.__pydantic_validator__.validate_python(
pydantic_core._pydantic_core.ValidationError: 1 validation error for Product
retail_price
  Field required [type=missing, input_value=<app.models.product.Product object at 0x11a347610>, input_type=Product]
    For further information visit https://errors.pydantic.dev/2.5/v/missing
INFO:     127.0.0.1:51375 - "GET /api/products/ HTTP/1.1" 500 Internal Server Error
ERROR:    Exception in ASGI application
Traceback (most recent call last):
  File "/Users/alekenov/projects/shadcn-test/backend/venv/lib/python3.9/site-packages/uvicorn/protocols/http/httptools_impl.py", line 426, in run_asgi
    result = await app(  # type: ignore[func-returns-value]
  File "/Users/alekenov/projects/shadcn-test/backend/venv/lib/python3.9/site-packages/uvicorn/middleware/proxy_headers.py", line 84, in __call__
    return await self.app(scope, receive, send)
  File "/Users/alekenov/projects/shadcn-test/backend/venv/lib/python3.9/site-packages/fastapi/applications.py", line 1054, in __call__
    await super().__call__(scope, receive, send)
  File "/Users/alekenov/projects/shadcn-test/backend/venv/lib/python3.9/site-packages/starlette/applications.py", line 123, in __call__
    await self.middleware_stack(scope, receive, send)
  File "/Users/alekenov/projects/shadcn-test/backend/venv/lib/python3.9/site-packages/starlette/middleware/errors.py", line 186, in __call__
    raise exc
  File "/Users/alekenov/projects/shadcn-test/backend/venv/lib/python3.9/site-packages/starlette/middleware/errors.py", line 164, in __call__
    await self.app(scope, receive, _send)
  File "/Users/alekenov/projects/shadcn-test/backend/venv/lib/python3.9/site-packages/starlette/middleware/cors.py", line 83, in __call__
    await self.app(scope, receive, send)
  File "/Users/alekenov/projects/shadcn-test/backend/venv/lib/python3.9/site-packages/starlette/middleware/exceptions.py", line 62, in __call__
    await wrap_app_handling_exceptions(self.app, conn)(scope, receive, send)
  File "/Users/alekenov/projects/shadcn-test/backend/venv/lib/python3.9/site-packages/starlette/_exception_handler.py", line 64, in wrapped_app
    raise exc
  File "/Users/alekenov/projects/shadcn-test/backend/venv/lib/python3.9/site-packages/starlette/_exception_handler.py", line 53, in wrapped_app
    await app(scope, receive, sender)
  File "/Users/alekenov/projects/shadcn-test/backend/venv/lib/python3.9/site-packages/starlette/routing.py", line 762, in __call__
    await self.middleware_stack(scope, receive, send)
  File "/Users/alekenov/projects/shadcn-test/backend/venv/lib/python3.9/site-packages/starlette/routing.py", line 782, in app
    await route.handle(scope, receive, send)
  File "/Users/alekenov/projects/shadcn-test/backend/venv/lib/python3.9/site-packages/starlette/routing.py", line 297, in handle
    await self.app(scope, receive, send)
  File "/Users/alekenov/projects/shadcn-test/backend/venv/lib/python3.9/site-packages/starlette/routing.py", line 77, in app
    await wrap_app_handling_exceptions(app, request)(scope, receive, send)
  File "/Users/alekenov/projects/shadcn-test/backend/venv/lib/python3.9/site-packages/starlette/_exception_handler.py", line 64, in wrapped_app
    raise exc
  File "/Users/alekenov/projects/shadcn-test/backend/venv/lib/python3.9/site-packages/starlette/_exception_handler.py", line 53, in wrapped_app
    await app(scope, receive, sender)
  File "/Users/alekenov/projects/shadcn-test/backend/venv/lib/python3.9/site-packages/starlette/routing.py", line 72, in app
    response = await func(request)
  File "/Users/alekenov/projects/shadcn-test/backend/venv/lib/python3.9/site-packages/fastapi/routing.py", line 299, in app
    raise e
  File "/Users/alekenov/projects/shadcn-test/backend/venv/lib/python3.9/site-packages/fastapi/routing.py", line 294, in app
    raw_response = await run_endpoint_function(
  File "/Users/alekenov/projects/shadcn-test/backend/venv/lib/python3.9/site-packages/fastapi/routing.py", line 193, in run_endpoint_function
    return await run_in_threadpool(dependant.call, **values)
  File "/Users/alekenov/projects/shadcn-test/backend/venv/lib/python3.9/site-packages/starlette/concurrency.py", line 40, in run_in_threadpool
    return await anyio.to_thread.run_sync(func, *args)
  File "/Users/alekenov/projects/shadcn-test/backend/venv/lib/python3.9/site-packages/anyio/to_thread.py", line 56, in run_sync
    return await get_async_backend().run_sync_in_worker_thread(
  File "/Users/alekenov/projects/shadcn-test/backend/venv/lib/python3.9/site-packages/anyio/_backends/_asyncio.py", line 2470, in run_sync_in_worker_thread
    return await future
  File "/Users/alekenov/projects/shadcn-test/backend/venv/lib/python3.9/site-packages/anyio/_backends/_asyncio.py", line 967, in run
    result = context.run(func, *args)
  File "/Users/alekenov/projects/shadcn-test/backend/app/api/endpoints/products.py", line 60, in read_products
    product_schemas = [schemas.Product.from_orm(product) for product in products]
  File "/Users/alekenov/projects/shadcn-test/backend/app/api/endpoints/products.py", line 60, in <listcomp>
    product_schemas = [schemas.Product.from_orm(product) for product in products]
  File "/Users/alekenov/projects/shadcn-test/backend/venv/lib/python3.9/site-packages/typing_extensions.py", line 2956, in wrapper
    return arg(*args, **kwargs)
  File "/Users/alekenov/projects/shadcn-test/backend/venv/lib/python3.9/site-packages/pydantic/main.py", line 1129, in from_orm
    return cls.model_validate(obj)
  File "/Users/alekenov/projects/shadcn-test/backend/venv/lib/python3.9/site-packages/pydantic/main.py", line 503, in model_validate
    return cls.__pydantic_validator__.validate_python(
pydantic_core._pydantic_core.ValidationError: 1 validation error for Product
retail_price
  Field required [type=missing, input_value=<app.models.product.Product object at 0x11a0afe20>, input_type=Product]
    For further information visit https://errors.pydantic.dev/2.5/v/missing
INFO:     127.0.0.1:51423 - "GET /api/auth/me HTTP/1.1" 200 OK
INFO:     127.0.0.1:51422 - "GET /api/products/ HTTP/1.1" 500 Internal Server Error
ERROR:    Exception in ASGI application
Traceback (most recent call last):
  File "/Users/alekenov/projects/shadcn-test/backend/venv/lib/python3.9/site-packages/uvicorn/protocols/http/httptools_impl.py", line 426, in run_asgi
    result = await app(  # type: ignore[func-returns-value]
  File "/Users/alekenov/projects/shadcn-test/backend/venv/lib/python3.9/site-packages/uvicorn/middleware/proxy_headers.py", line 84, in __call__
    return await self.app(scope, receive, send)
  File "/Users/alekenov/projects/shadcn-test/backend/venv/lib/python3.9/site-packages/fastapi/applications.py", line 1054, in __call__
    await super().__call__(scope, receive, send)
  File "/Users/alekenov/projects/shadcn-test/backend/venv/lib/python3.9/site-packages/starlette/applications.py", line 123, in __call__
    await self.middleware_stack(scope, receive, send)
  File "/Users/alekenov/projects/shadcn-test/backend/venv/lib/python3.9/site-packages/starlette/middleware/errors.py", line 186, in __call__
    raise exc
  File "/Users/alekenov/projects/shadcn-test/backend/venv/lib/python3.9/site-packages/starlette/middleware/errors.py", line 164, in __call__
    await self.app(scope, receive, _send)
  File "/Users/alekenov/projects/shadcn-test/backend/venv/lib/python3.9/site-packages/starlette/middleware/cors.py", line 83, in __call__
    await self.app(scope, receive, send)
  File "/Users/alekenov/projects/shadcn-test/backend/venv/lib/python3.9/site-packages/starlette/middleware/exceptions.py", line 62, in __call__
    await wrap_app_handling_exceptions(self.app, conn)(scope, receive, send)
  File "/Users/alekenov/projects/shadcn-test/backend/venv/lib/python3.9/site-packages/starlette/_exception_handler.py", line 64, in wrapped_app
    raise exc
  File "/Users/alekenov/projects/shadcn-test/backend/venv/lib/python3.9/site-packages/starlette/_exception_handler.py", line 53, in wrapped_app
    await app(scope, receive, sender)
  File "/Users/alekenov/projects/shadcn-test/backend/venv/lib/python3.9/site-packages/starlette/routing.py", line 762, in __call__
    await self.middleware_stack(scope, receive, send)
  File "/Users/alekenov/projects/shadcn-test/backend/venv/lib/python3.9/site-packages/starlette/routing.py", line 782, in app
    await route.handle(scope, receive, send)
  File "/Users/alekenov/projects/shadcn-test/backend/venv/lib/python3.9/site-packages/starlette/routing.py", line 297, in handle
    await self.app(scope, receive, send)
  File "/Users/alekenov/projects/shadcn-test/backend/venv/lib/python3.9/site-packages/starlette/routing.py", line 77, in app
    await wrap_app_handling_exceptions(app, request)(scope, receive, send)
  File "/Users/alekenov/projects/shadcn-test/backend/venv/lib/python3.9/site-packages/starlette/_exception_handler.py", line 64, in wrapped_app
    raise exc
  File "/Users/alekenov/projects/shadcn-test/backend/venv/lib/python3.9/site-packages/starlette/_exception_handler.py", line 53, in wrapped_app
    await app(scope, receive, sender)
  File "/Users/alekenov/projects/shadcn-test/backend/venv/lib/python3.9/site-packages/starlette/routing.py", line 72, in app
    response = await func(request)
  File "/Users/alekenov/projects/shadcn-test/backend/venv/lib/python3.9/site-packages/fastapi/routing.py", line 299, in app
    raise e
  File "/Users/alekenov/projects/shadcn-test/backend/venv/lib/python3.9/site-packages/fastapi/routing.py", line 294, in app
    raw_response = await run_endpoint_function(
  File "/Users/alekenov/projects/shadcn-test/backend/venv/lib/python3.9/site-packages/fastapi/routing.py", line 193, in run_endpoint_function
    return await run_in_threadpool(dependant.call, **values)
  File "/Users/alekenov/projects/shadcn-test/backend/venv/lib/python3.9/site-packages/starlette/concurrency.py", line 40, in run_in_threadpool
    return await anyio.to_thread.run_sync(func, *args)
  File "/Users/alekenov/projects/shadcn-test/backend/venv/lib/python3.9/site-packages/anyio/to_thread.py", line 56, in run_sync
    return await get_async_backend().run_sync_in_worker_thread(
  File "/Users/alekenov/projects/shadcn-test/backend/venv/lib/python3.9/site-packages/anyio/_backends/_asyncio.py", line 2470, in run_sync_in_worker_thread
    return await future
  File "/Users/alekenov/projects/shadcn-test/backend/venv/lib/python3.9/site-packages/anyio/_backends/_asyncio.py", line 967, in run
    result = context.run(func, *args)
  File "/Users/alekenov/projects/shadcn-test/backend/app/api/endpoints/products.py", line 60, in read_products
    product_schemas = [schemas.Product.from_orm(product) for product in products]
  File "/Users/alekenov/projects/shadcn-test/backend/app/api/endpoints/products.py", line 60, in <listcomp>
    product_schemas = [schemas.Product.from_orm(product) for product in products]
  File "/Users/alekenov/projects/shadcn-test/backend/venv/lib/python3.9/site-packages/typing_extensions.py", line 2956, in wrapper
    return arg(*args, **kwargs)
  File "/Users/alekenov/projects/shadcn-test/backend/venv/lib/python3.9/site-packages/pydantic/main.py", line 1129, in from_orm
    return cls.model_validate(obj)
  File "/Users/alekenov/projects/shadcn-test/backend/venv/lib/python3.9/site-packages/pydantic/main.py", line 503, in model_validate
    return cls.__pydantic_validator__.validate_python(
pydantic_core._pydantic_core.ValidationError: 1 validation error for Product
retail_price
  Field required [type=missing, input_value=<app.models.product.Product object at 0x11a0949a0>, input_type=Product]
    For further information visit https://errors.pydantic.dev/2.5/v/missing
INFO:     127.0.0.1:51425 - "GET /api/auth/me HTTP/1.1" 200 OK
INFO:     127.0.0.1:51427 - "GET /api/products/ HTTP/1.1" 500 Internal Server Error
ERROR:    Exception in ASGI application
Traceback (most recent call last):
  File "/Users/alekenov/projects/shadcn-test/backend/venv/lib/python3.9/site-packages/uvicorn/protocols/http/httptools_impl.py", line 426, in run_asgi
    result = await app(  # type: ignore[func-returns-value]
  File "/Users/alekenov/projects/shadcn-test/backend/venv/lib/python3.9/site-packages/uvicorn/middleware/proxy_headers.py", line 84, in __call__
    return await self.app(scope, receive, send)
  File "/Users/alekenov/projects/shadcn-test/backend/venv/lib/python3.9/site-packages/fastapi/applications.py", line 1054, in __call__
    await super().__call__(scope, receive, send)
  File "/Users/alekenov/projects/shadcn-test/backend/venv/lib/python3.9/site-packages/starlette/applications.py", line 123, in __call__
    await self.middleware_stack(scope, receive, send)
  File "/Users/alekenov/projects/shadcn-test/backend/venv/lib/python3.9/site-packages/starlette/middleware/errors.py", line 186, in __call__
    raise exc
  File "/Users/alekenov/projects/shadcn-test/backend/venv/lib/python3.9/site-packages/starlette/middleware/errors.py", line 164, in __call__
    await self.app(scope, receive, _send)
  File "/Users/alekenov/projects/shadcn-test/backend/venv/lib/python3.9/site-packages/starlette/middleware/cors.py", line 83, in __call__
    await self.app(scope, receive, send)
  File "/Users/alekenov/projects/shadcn-test/backend/venv/lib/python3.9/site-packages/starlette/middleware/exceptions.py", line 62, in __call__
    await wrap_app_handling_exceptions(self.app, conn)(scope, receive, send)
  File "/Users/alekenov/projects/shadcn-test/backend/venv/lib/python3.9/site-packages/starlette/_exception_handler.py", line 64, in wrapped_app
    raise exc
  File "/Users/alekenov/projects/shadcn-test/backend/venv/lib/python3.9/site-packages/starlette/_exception_handler.py", line 53, in wrapped_app
    await app(scope, receive, sender)
  File "/Users/alekenov/projects/shadcn-test/backend/venv/lib/python3.9/site-packages/starlette/routing.py", line 762, in __call__
    await self.middleware_stack(scope, receive, send)
  File "/Users/alekenov/projects/shadcn-test/backend/venv/lib/python3.9/site-packages/starlette/routing.py", line 782, in app
    await route.handle(scope, receive, send)
  File "/Users/alekenov/projects/shadcn-test/backend/venv/lib/python3.9/site-packages/starlette/routing.py", line 297, in handle
    await self.app(scope, receive, send)
  File "/Users/alekenov/projects/shadcn-test/backend/venv/lib/python3.9/site-packages/starlette/routing.py", line 77, in app
    await wrap_app_handling_exceptions(app, request)(scope, receive, send)
  File "/Users/alekenov/projects/shadcn-test/backend/venv/lib/python3.9/site-packages/starlette/_exception_handler.py", line 64, in wrapped_app
    raise exc
  File "/Users/alekenov/projects/shadcn-test/backend/venv/lib/python3.9/site-packages/starlette/_exception_handler.py", line 53, in wrapped_app
    await app(scope, receive, sender)
  File "/Users/alekenov/projects/shadcn-test/backend/venv/lib/python3.9/site-packages/starlette/routing.py", line 72, in app
    response = await func(request)
  File "/Users/alekenov/projects/shadcn-test/backend/venv/lib/python3.9/site-packages/fastapi/routing.py", line 299, in app
    raise e
  File "/Users/alekenov/projects/shadcn-test/backend/venv/lib/python3.9/site-packages/fastapi/routing.py", line 294, in app
    raw_response = await run_endpoint_function(
  File "/Users/alekenov/projects/shadcn-test/backend/venv/lib/python3.9/site-packages/fastapi/routing.py", line 193, in run_endpoint_function
    return await run_in_threadpool(dependant.call, **values)
  File "/Users/alekenov/projects/shadcn-test/backend/venv/lib/python3.9/site-packages/starlette/concurrency.py", line 40, in run_in_threadpool
    return await anyio.to_thread.run_sync(func, *args)
  File "/Users/alekenov/projects/shadcn-test/backend/venv/lib/python3.9/site-packages/anyio/to_thread.py", line 56, in run_sync
    return await get_async_backend().run_sync_in_worker_thread(
  File "/Users/alekenov/projects/shadcn-test/backend/venv/lib/python3.9/site-packages/anyio/_backends/_asyncio.py", line 2470, in run_sync_in_worker_thread
    return await future
  File "/Users/alekenov/projects/shadcn-test/backend/venv/lib/python3.9/site-packages/anyio/_backends/_asyncio.py", line 967, in run
    result = context.run(func, *args)
  File "/Users/alekenov/projects/shadcn-test/backend/app/api/endpoints/products.py", line 60, in read_products
    product_schemas = [schemas.Product.from_orm(product) for product in products]
  File "/Users/alekenov/projects/shadcn-test/backend/app/api/endpoints/products.py", line 60, in <listcomp>
    product_schemas = [schemas.Product.from_orm(product) for product in products]
  File "/Users/alekenov/projects/shadcn-test/backend/venv/lib/python3.9/site-packages/typing_extensions.py", line 2956, in wrapper
    return arg(*args, **kwargs)
  File "/Users/alekenov/projects/shadcn-test/backend/venv/lib/python3.9/site-packages/pydantic/main.py", line 1129, in from_orm
    return cls.model_validate(obj)
  File "/Users/alekenov/projects/shadcn-test/backend/venv/lib/python3.9/site-packages/pydantic/main.py", line 503, in model_validate
    return cls.__pydantic_validator__.validate_python(
pydantic_core._pydantic_core.ValidationError: 1 validation error for Product
retail_price
  Field required [type=missing, input_value=<app.models.product.Product object at 0x11a34eac0>, input_type=Product]
    For further information visit https://errors.pydantic.dev/2.5/v/missing
INFO:     127.0.0.1:51429 - "GET /api/products/ HTTP/1.1" 500 Internal Server Error
ERROR:    Exception in ASGI application
Traceback (most recent call last):
  File "/Users/alekenov/projects/shadcn-test/backend/venv/lib/python3.9/site-packages/uvicorn/protocols/http/httptools_impl.py", line 426, in run_asgi
    result = await app(  # type: ignore[func-returns-value]
  File "/Users/alekenov/projects/shadcn-test/backend/venv/lib/python3.9/site-packages/uvicorn/middleware/proxy_headers.py", line 84, in __call__
    return await self.app(scope, receive, send)
  File "/Users/alekenov/projects/shadcn-test/backend/venv/lib/python3.9/site-packages/fastapi/applications.py", line 1054, in __call__
    await super().__call__(scope, receive, send)
  File "/Users/alekenov/projects/shadcn-test/backend/venv/lib/python3.9/site-packages/starlette/applications.py", line 123, in __call__
    await self.middleware_stack(scope, receive, send)
  File "/Users/alekenov/projects/shadcn-test/backend/venv/lib/python3.9/site-packages/starlette/middleware/errors.py", line 186, in __call__
    raise exc
  File "/Users/alekenov/projects/shadcn-test/backend/venv/lib/python3.9/site-packages/starlette/middleware/errors.py", line 164, in __call__
    await self.app(scope, receive, _send)
  File "/Users/alekenov/projects/shadcn-test/backend/venv/lib/python3.9/site-packages/starlette/middleware/cors.py", line 83, in __call__
    await self.app(scope, receive, send)
  File "/Users/alekenov/projects/shadcn-test/backend/venv/lib/python3.9/site-packages/starlette/middleware/exceptions.py", line 62, in __call__
    await wrap_app_handling_exceptions(self.app, conn)(scope, receive, send)
  File "/Users/alekenov/projects/shadcn-test/backend/venv/lib/python3.9/site-packages/starlette/_exception_handler.py", line 64, in wrapped_app
    raise exc
  File "/Users/alekenov/projects/shadcn-test/backend/venv/lib/python3.9/site-packages/starlette/_exception_handler.py", line 53, in wrapped_app
    await app(scope, receive, sender)
  File "/Users/alekenov/projects/shadcn-test/backend/venv/lib/python3.9/site-packages/starlette/routing.py", line 762, in __call__
    await self.middleware_stack(scope, receive, send)
  File "/Users/alekenov/projects/shadcn-test/backend/venv/lib/python3.9/site-packages/starlette/routing.py", line 782, in app
    await route.handle(scope, receive, send)
  File "/Users/alekenov/projects/shadcn-test/backend/venv/lib/python3.9/site-packages/starlette/routing.py", line 297, in handle
    await self.app(scope, receive, send)
  File "/Users/alekenov/projects/shadcn-test/backend/venv/lib/python3.9/site-packages/starlette/routing.py", line 77, in app
    await wrap_app_handling_exceptions(app, request)(scope, receive, send)
  File "/Users/alekenov/projects/shadcn-test/backend/venv/lib/python3.9/site-packages/starlette/_exception_handler.py", line 64, in wrapped_app
    raise exc
  File "/Users/alekenov/projects/shadcn-test/backend/venv/lib/python3.9/site-packages/starlette/_exception_handler.py", line 53, in wrapped_app
    await app(scope, receive, sender)
  File "/Users/alekenov/projects/shadcn-test/backend/venv/lib/python3.9/site-packages/starlette/routing.py", line 72, in app
    response = await func(request)
  File "/Users/alekenov/projects/shadcn-test/backend/venv/lib/python3.9/site-packages/fastapi/routing.py", line 299, in app
    raise e
  File "/Users/alekenov/projects/shadcn-test/backend/venv/lib/python3.9/site-packages/fastapi/routing.py", line 294, in app
    raw_response = await run_endpoint_function(
  File "/Users/alekenov/projects/shadcn-test/backend/venv/lib/python3.9/site-packages/fastapi/routing.py", line 193, in run_endpoint_function
    return await run_in_threadpool(dependant.call, **values)
  File "/Users/alekenov/projects/shadcn-test/backend/venv/lib/python3.9/site-packages/starlette/concurrency.py", line 40, in run_in_threadpool
    return await anyio.to_thread.run_sync(func, *args)
  File "/Users/alekenov/projects/shadcn-test/backend/venv/lib/python3.9/site-packages/anyio/to_thread.py", line 56, in run_sync
    return await get_async_backend().run_sync_in_worker_thread(
  File "/Users/alekenov/projects/shadcn-test/backend/venv/lib/python3.9/site-packages/anyio/_backends/_asyncio.py", line 2470, in run_sync_in_worker_thread
    return await future
  File "/Users/alekenov/projects/shadcn-test/backend/venv/lib/python3.9/site-packages/anyio/_backends/_asyncio.py", line 967, in run
    result = context.run(func, *args)
  File "/Users/alekenov/projects/shadcn-test/backend/app/api/endpoints/products.py", line 60, in read_products
    product_schemas = [schemas.Product.from_orm(product) for product in products]
  File "/Users/alekenov/projects/shadcn-test/backend/app/api/endpoints/products.py", line 60, in <listcomp>
    product_schemas = [schemas.Product.from_orm(product) for product in products]
  File "/Users/alekenov/projects/shadcn-test/backend/venv/lib/python3.9/site-packages/typing_extensions.py", line 2956, in wrapper
    return arg(*args, **kwargs)
  File "/Users/alekenov/projects/shadcn-test/backend/venv/lib/python3.9/site-packages/pydantic/main.py", line 1129, in from_orm
    return cls.model_validate(obj)
  File "/Users/alekenov/projects/shadcn-test/backend/venv/lib/python3.9/site-packages/pydantic/main.py", line 503, in model_validate
    return cls.__pydantic_validator__.validate_python(
pydantic_core._pydantic_core.ValidationError: 1 validation error for Product
retail_price
  Field required [type=missing, input_value=<app.models.product.Product object at 0x11a35dee0>, input_type=Product]
    For further information visit https://errors.pydantic.dev/2.5/v/missing
INFO:     127.0.0.1:51431 - "GET /api/products/ HTTP/1.1" 500 Internal Server Error
ERROR:    Exception in ASGI application
Traceback (most recent call last):
  File "/Users/alekenov/projects/shadcn-test/backend/venv/lib/python3.9/site-packages/uvicorn/protocols/http/httptools_impl.py", line 426, in run_asgi
    result = await app(  # type: ignore[func-returns-value]
  File "/Users/alekenov/projects/shadcn-test/backend/venv/lib/python3.9/site-packages/uvicorn/middleware/proxy_headers.py", line 84, in __call__
    return await self.app(scope, receive, send)
  File "/Users/alekenov/projects/shadcn-test/backend/venv/lib/python3.9/site-packages/fastapi/applications.py", line 1054, in __call__
    await super().__call__(scope, receive, send)
  File "/Users/alekenov/projects/shadcn-test/backend/venv/lib/python3.9/site-packages/starlette/applications.py", line 123, in __call__
    await self.middleware_stack(scope, receive, send)
  File "/Users/alekenov/projects/shadcn-test/backend/venv/lib/python3.9/site-packages/starlette/middleware/errors.py", line 186, in __call__
    raise exc
  File "/Users/alekenov/projects/shadcn-test/backend/venv/lib/python3.9/site-packages/starlette/middleware/errors.py", line 164, in __call__
    await self.app(scope, receive, _send)
  File "/Users/alekenov/projects/shadcn-test/backend/venv/lib/python3.9/site-packages/starlette/middleware/cors.py", line 83, in __call__
    await self.app(scope, receive, send)
  File "/Users/alekenov/projects/shadcn-test/backend/venv/lib/python3.9/site-packages/starlette/middleware/exceptions.py", line 62, in __call__
    await wrap_app_handling_exceptions(self.app, conn)(scope, receive, send)
  File "/Users/alekenov/projects/shadcn-test/backend/venv/lib/python3.9/site-packages/starlette/_exception_handler.py", line 64, in wrapped_app
    raise exc
  File "/Users/alekenov/projects/shadcn-test/backend/venv/lib/python3.9/site-packages/starlette/_exception_handler.py", line 53, in wrapped_app
    await app(scope, receive, sender)
  File "/Users/alekenov/projects/shadcn-test/backend/venv/lib/python3.9/site-packages/starlette/routing.py", line 762, in __call__
    await self.middleware_stack(scope, receive, send)
  File "/Users/alekenov/projects/shadcn-test/backend/venv/lib/python3.9/site-packages/starlette/routing.py", line 782, in app
    await route.handle(scope, receive, send)
  File "/Users/alekenov/projects/shadcn-test/backend/venv/lib/python3.9/site-packages/starlette/routing.py", line 297, in handle
    await self.app(scope, receive, send)
  File "/Users/alekenov/projects/shadcn-test/backend/venv/lib/python3.9/site-packages/starlette/routing.py", line 77, in app
    await wrap_app_handling_exceptions(app, request)(scope, receive, send)
  File "/Users/alekenov/projects/shadcn-test/backend/venv/lib/python3.9/site-packages/starlette/_exception_handler.py", line 64, in wrapped_app
    raise exc
  File "/Users/alekenov/projects/shadcn-test/backend/venv/lib/python3.9/site-packages/starlette/_exception_handler.py", line 53, in wrapped_app
    await app(scope, receive, sender)
  File "/Users/alekenov/projects/shadcn-test/backend/venv/lib/python3.9/site-packages/starlette/routing.py", line 72, in app
    response = await func(request)
  File "/Users/alekenov/projects/shadcn-test/backend/venv/lib/python3.9/site-packages/fastapi/routing.py", line 299, in app
    raise e
  File "/Users/alekenov/projects/shadcn-test/backend/venv/lib/python3.9/site-packages/fastapi/routing.py", line 294, in app
    raw_response = await run_endpoint_function(
  File "/Users/alekenov/projects/shadcn-test/backend/venv/lib/python3.9/site-packages/fastapi/routing.py", line 193, in run_endpoint_function
    return await run_in_threadpool(dependant.call, **values)
  File "/Users/alekenov/projects/shadcn-test/backend/venv/lib/python3.9/site-packages/starlette/concurrency.py", line 40, in run_in_threadpool
    return await anyio.to_thread.run_sync(func, *args)
  File "/Users/alekenov/projects/shadcn-test/backend/venv/lib/python3.9/site-packages/anyio/to_thread.py", line 56, in run_sync
    return await get_async_backend().run_sync_in_worker_thread(
  File "/Users/alekenov/projects/shadcn-test/backend/venv/lib/python3.9/site-packages/anyio/_backends/_asyncio.py", line 2470, in run_sync_in_worker_thread
    return await future
  File "/Users/alekenov/projects/shadcn-test/backend/venv/lib/python3.9/site-packages/anyio/_backends/_asyncio.py", line 967, in run
    result = context.run(func, *args)
  File "/Users/alekenov/projects/shadcn-test/backend/app/api/endpoints/products.py", line 60, in read_products
    product_schemas = [schemas.Product.from_orm(product) for product in products]
  File "/Users/alekenov/projects/shadcn-test/backend/app/api/endpoints/products.py", line 60, in <listcomp>
    product_schemas = [schemas.Product.from_orm(product) for product in products]
  File "/Users/alekenov/projects/shadcn-test/backend/venv/lib/python3.9/site-packages/typing_extensions.py", line 2956, in wrapper
    return arg(*args, **kwargs)
  File "/Users/alekenov/projects/shadcn-test/backend/venv/lib/python3.9/site-packages/pydantic/main.py", line 1129, in from_orm
    return cls.model_validate(obj)
  File "/Users/alekenov/projects/shadcn-test/backend/venv/lib/python3.9/site-packages/pydantic/main.py", line 503, in model_validate
    return cls.__pydantic_validator__.validate_python(
pydantic_core._pydantic_core.ValidationError: 1 validation error for Product
retail_price
  Field required [type=missing, input_value=<app.models.product.Product object at 0x11a3682b0>, input_type=Product]
    For further information visit https://errors.pydantic.dev/2.5/v/missing
INFO:     127.0.0.1:51452 - "GET /api/auth/me HTTP/1.1" 200 OK
INFO:     127.0.0.1:51451 - "GET /api/warehouse/?page=1&limit=20 HTTP/1.1" 200 OK
INFO:     127.0.0.1:51454 - "GET /api/auth/me HTTP/1.1" 200 OK
INFO:     127.0.0.1:51469 - "GET /api/auth/me HTTP/1.1" 200 OK
INFO:     127.0.0.1:51471 - "GET /api/auth/me HTTP/1.1" 200 OK
INFO:     127.0.0.1:51468 - "GET /api/orders/?page=1&limit=20 HTTP/1.1" 200 OK
INFO:     127.0.0.1:51630 - "GET /api/auth/me HTTP/1.1" 200 OK
INFO:     127.0.0.1:51632 - "GET /api/auth/me HTTP/1.1" 200 OK
INFO:     127.0.0.1:51629 - "GET /api/orders/?page=1&limit=20 HTTP/1.1" 200 OK
INFO:     127.0.0.1:51656 - "GET /api/auth/me HTTP/1.1" 200 OK
INFO:     127.0.0.1:51654 - "GET /api/orders/?page=1&limit=20 HTTP/1.1" 200 OK
INFO:     127.0.0.1:51658 - "GET /api/auth/me HTTP/1.1" 200 OK
INFO:     127.0.0.1:51665 - "GET /api/products/ HTTP/1.1" 500 Internal Server Error
ERROR:    Exception in ASGI application
Traceback (most recent call last):
  File "/Users/alekenov/projects/shadcn-test/backend/venv/lib/python3.9/site-packages/uvicorn/protocols/http/httptools_impl.py", line 426, in run_asgi
    result = await app(  # type: ignore[func-returns-value]
  File "/Users/alekenov/projects/shadcn-test/backend/venv/lib/python3.9/site-packages/uvicorn/middleware/proxy_headers.py", line 84, in __call__
    return await self.app(scope, receive, send)
  File "/Users/alekenov/projects/shadcn-test/backend/venv/lib/python3.9/site-packages/fastapi/applications.py", line 1054, in __call__
    await super().__call__(scope, receive, send)
  File "/Users/alekenov/projects/shadcn-test/backend/venv/lib/python3.9/site-packages/starlette/applications.py", line 123, in __call__
    await self.middleware_stack(scope, receive, send)
  File "/Users/alekenov/projects/shadcn-test/backend/venv/lib/python3.9/site-packages/starlette/middleware/errors.py", line 186, in __call__
    raise exc
  File "/Users/alekenov/projects/shadcn-test/backend/venv/lib/python3.9/site-packages/starlette/middleware/errors.py", line 164, in __call__
    await self.app(scope, receive, _send)
  File "/Users/alekenov/projects/shadcn-test/backend/venv/lib/python3.9/site-packages/starlette/middleware/cors.py", line 83, in __call__
    await self.app(scope, receive, send)
  File "/Users/alekenov/projects/shadcn-test/backend/venv/lib/python3.9/site-packages/starlette/middleware/exceptions.py", line 62, in __call__
    await wrap_app_handling_exceptions(self.app, conn)(scope, receive, send)
  File "/Users/alekenov/projects/shadcn-test/backend/venv/lib/python3.9/site-packages/starlette/_exception_handler.py", line 64, in wrapped_app
    raise exc
  File "/Users/alekenov/projects/shadcn-test/backend/venv/lib/python3.9/site-packages/starlette/_exception_handler.py", line 53, in wrapped_app
    await app(scope, receive, sender)
  File "/Users/alekenov/projects/shadcn-test/backend/venv/lib/python3.9/site-packages/starlette/routing.py", line 762, in __call__
    await self.middleware_stack(scope, receive, send)
  File "/Users/alekenov/projects/shadcn-test/backend/venv/lib/python3.9/site-packages/starlette/routing.py", line 782, in app
    await route.handle(scope, receive, send)
  File "/Users/alekenov/projects/shadcn-test/backend/venv/lib/python3.9/site-packages/starlette/routing.py", line 297, in handle
    await self.app(scope, receive, send)
  File "/Users/alekenov/projects/shadcn-test/backend/venv/lib/python3.9/site-packages/starlette/routing.py", line 77, in app
    await wrap_app_handling_exceptions(app, request)(scope, receive, send)
  File "/Users/alekenov/projects/shadcn-test/backend/venv/lib/python3.9/site-packages/starlette/_exception_handler.py", line 64, in wrapped_app
    raise exc
  File "/Users/alekenov/projects/shadcn-test/backend/venv/lib/python3.9/site-packages/starlette/_exception_handler.py", line 53, in wrapped_app
    await app(scope, receive, sender)
  File "/Users/alekenov/projects/shadcn-test/backend/venv/lib/python3.9/site-packages/starlette/routing.py", line 72, in app
    response = await func(request)
  File "/Users/alekenov/projects/shadcn-test/backend/venv/lib/python3.9/site-packages/fastapi/routing.py", line 299, in app
    raise e
  File "/Users/alekenov/projects/shadcn-test/backend/venv/lib/python3.9/site-packages/fastapi/routing.py", line 294, in app
    raw_response = await run_endpoint_function(
  File "/Users/alekenov/projects/shadcn-test/backend/venv/lib/python3.9/site-packages/fastapi/routing.py", line 193, in run_endpoint_function
    return await run_in_threadpool(dependant.call, **values)
  File "/Users/alekenov/projects/shadcn-test/backend/venv/lib/python3.9/site-packages/starlette/concurrency.py", line 40, in run_in_threadpool
    return await anyio.to_thread.run_sync(func, *args)
  File "/Users/alekenov/projects/shadcn-test/backend/venv/lib/python3.9/site-packages/anyio/to_thread.py", line 56, in run_sync
    return await get_async_backend().run_sync_in_worker_thread(
  File "/Users/alekenov/projects/shadcn-test/backend/venv/lib/python3.9/site-packages/anyio/_backends/_asyncio.py", line 2470, in run_sync_in_worker_thread
    return await future
  File "/Users/alekenov/projects/shadcn-test/backend/venv/lib/python3.9/site-packages/anyio/_backends/_asyncio.py", line 967, in run
    result = context.run(func, *args)
  File "/Users/alekenov/projects/shadcn-test/backend/app/api/endpoints/products.py", line 60, in read_products
    product_schemas = [schemas.Product.from_orm(product) for product in products]
  File "/Users/alekenov/projects/shadcn-test/backend/app/api/endpoints/products.py", line 60, in <listcomp>
    product_schemas = [schemas.Product.from_orm(product) for product in products]
  File "/Users/alekenov/projects/shadcn-test/backend/venv/lib/python3.9/site-packages/typing_extensions.py", line 2956, in wrapper
    return arg(*args, **kwargs)
  File "/Users/alekenov/projects/shadcn-test/backend/venv/lib/python3.9/site-packages/pydantic/main.py", line 1129, in from_orm
    return cls.model_validate(obj)
  File "/Users/alekenov/projects/shadcn-test/backend/venv/lib/python3.9/site-packages/pydantic/main.py", line 503, in model_validate
    return cls.__pydantic_validator__.validate_python(
pydantic_core._pydantic_core.ValidationError: 1 validation error for Product
retail_price
  Field required [type=missing, input_value=<app.models.product.Product object at 0x11a35df70>, input_type=Product]
    For further information visit https://errors.pydantic.dev/2.5/v/missing
INFO:     127.0.0.1:51691 - "GET /api/products/ HTTP/1.1" 500 Internal Server Error
ERROR:    Exception in ASGI application
Traceback (most recent call last):
  File "/Users/alekenov/projects/shadcn-test/backend/venv/lib/python3.9/site-packages/uvicorn/protocols/http/httptools_impl.py", line 426, in run_asgi
    result = await app(  # type: ignore[func-returns-value]
  File "/Users/alekenov/projects/shadcn-test/backend/venv/lib/python3.9/site-packages/uvicorn/middleware/proxy_headers.py", line 84, in __call__
    return await self.app(scope, receive, send)
  File "/Users/alekenov/projects/shadcn-test/backend/venv/lib/python3.9/site-packages/fastapi/applications.py", line 1054, in __call__
    await super().__call__(scope, receive, send)
  File "/Users/alekenov/projects/shadcn-test/backend/venv/lib/python3.9/site-packages/starlette/applications.py", line 123, in __call__
    await self.middleware_stack(scope, receive, send)
  File "/Users/alekenov/projects/shadcn-test/backend/venv/lib/python3.9/site-packages/starlette/middleware/errors.py", line 186, in __call__
    raise exc
  File "/Users/alekenov/projects/shadcn-test/backend/venv/lib/python3.9/site-packages/starlette/middleware/errors.py", line 164, in __call__
    await self.app(scope, receive, _send)
  File "/Users/alekenov/projects/shadcn-test/backend/venv/lib/python3.9/site-packages/starlette/middleware/cors.py", line 83, in __call__
    await self.app(scope, receive, send)
  File "/Users/alekenov/projects/shadcn-test/backend/venv/lib/python3.9/site-packages/starlette/middleware/exceptions.py", line 62, in __call__
    await wrap_app_handling_exceptions(self.app, conn)(scope, receive, send)
  File "/Users/alekenov/projects/shadcn-test/backend/venv/lib/python3.9/site-packages/starlette/_exception_handler.py", line 64, in wrapped_app
    raise exc
  File "/Users/alekenov/projects/shadcn-test/backend/venv/lib/python3.9/site-packages/starlette/_exception_handler.py", line 53, in wrapped_app
    await app(scope, receive, sender)
  File "/Users/alekenov/projects/shadcn-test/backend/venv/lib/python3.9/site-packages/starlette/routing.py", line 762, in __call__
    await self.middleware_stack(scope, receive, send)
  File "/Users/alekenov/projects/shadcn-test/backend/venv/lib/python3.9/site-packages/starlette/routing.py", line 782, in app
    await route.handle(scope, receive, send)
  File "/Users/alekenov/projects/shadcn-test/backend/venv/lib/python3.9/site-packages/starlette/routing.py", line 297, in handle
    await self.app(scope, receive, send)
  File "/Users/alekenov/projects/shadcn-test/backend/venv/lib/python3.9/site-packages/starlette/routing.py", line 77, in app
    await wrap_app_handling_exceptions(app, request)(scope, receive, send)
  File "/Users/alekenov/projects/shadcn-test/backend/venv/lib/python3.9/site-packages/starlette/_exception_handler.py", line 64, in wrapped_app
    raise exc
  File "/Users/alekenov/projects/shadcn-test/backend/venv/lib/python3.9/site-packages/starlette/_exception_handler.py", line 53, in wrapped_app
    await app(scope, receive, sender)
  File "/Users/alekenov/projects/shadcn-test/backend/venv/lib/python3.9/site-packages/starlette/routing.py", line 72, in app
    response = await func(request)
  File "/Users/alekenov/projects/shadcn-test/backend/venv/lib/python3.9/site-packages/fastapi/routing.py", line 299, in app
    raise e
  File "/Users/alekenov/projects/shadcn-test/backend/venv/lib/python3.9/site-packages/fastapi/routing.py", line 294, in app
    raw_response = await run_endpoint_function(
  File "/Users/alekenov/projects/shadcn-test/backend/venv/lib/python3.9/site-packages/fastapi/routing.py", line 193, in run_endpoint_function
    return await run_in_threadpool(dependant.call, **values)
  File "/Users/alekenov/projects/shadcn-test/backend/venv/lib/python3.9/site-packages/starlette/concurrency.py", line 40, in run_in_threadpool
    return await anyio.to_thread.run_sync(func, *args)
  File "/Users/alekenov/projects/shadcn-test/backend/venv/lib/python3.9/site-packages/anyio/to_thread.py", line 56, in run_sync
    return await get_async_backend().run_sync_in_worker_thread(
  File "/Users/alekenov/projects/shadcn-test/backend/venv/lib/python3.9/site-packages/anyio/_backends/_asyncio.py", line 2470, in run_sync_in_worker_thread
    return await future
  File "/Users/alekenov/projects/shadcn-test/backend/venv/lib/python3.9/site-packages/anyio/_backends/_asyncio.py", line 967, in run
    result = context.run(func, *args)
  File "/Users/alekenov/projects/shadcn-test/backend/app/api/endpoints/products.py", line 60, in read_products
    product_schemas = [schemas.Product.from_orm(product) for product in products]
  File "/Users/alekenov/projects/shadcn-test/backend/app/api/endpoints/products.py", line 60, in <listcomp>
    product_schemas = [schemas.Product.from_orm(product) for product in products]
  File "/Users/alekenov/projects/shadcn-test/backend/venv/lib/python3.9/site-packages/typing_extensions.py", line 2956, in wrapper
    return arg(*args, **kwargs)
  File "/Users/alekenov/projects/shadcn-test/backend/venv/lib/python3.9/site-packages/pydantic/main.py", line 1129, in from_orm
    return cls.model_validate(obj)
  File "/Users/alekenov/projects/shadcn-test/backend/venv/lib/python3.9/site-packages/pydantic/main.py", line 503, in model_validate
    return cls.__pydantic_validator__.validate_python(
pydantic_core._pydantic_core.ValidationError: 1 validation error for Product
retail_price
  Field required [type=missing, input_value=<app.models.product.Product object at 0x11a347d30>, input_type=Product]
    For further information visit https://errors.pydantic.dev/2.5/v/missing
INFO:     127.0.0.1:51785 - "GET /api/auth/me HTTP/1.1" 200 OK
INFO:     127.0.0.1:51787 - "GET /api/auth/me HTTP/1.1" 200 OK
INFO:     127.0.0.1:51784 - "GET /api/orders/?page=1&limit=20 HTTP/1.1" 200 OK
INFO:     127.0.0.1:51813 - "GET /api/auth/me HTTP/1.1" 200 OK
INFO:     127.0.0.1:51815 - "GET /api/auth/me HTTP/1.1" 200 OK
INFO:     127.0.0.1:51812 - "GET /api/orders/?page=1&limit=20 HTTP/1.1" 200 OK
INFO:     127.0.0.1:51841 - "GET /api/auth/me HTTP/1.1" 200 OK
INFO:     127.0.0.1:51844 - "GET /api/auth/me HTTP/1.1" 200 OK
INFO:     127.0.0.1:51842 - "GET /api/orders/?page=1&limit=20 HTTP/1.1" 200 OK
INFO:     127.0.0.1:51869 - "GET /api/auth/me HTTP/1.1" 200 OK
INFO:     127.0.0.1:51871 - "GET /api/auth/me HTTP/1.1" 200 OK
INFO:     127.0.0.1:51868 - "GET /api/orders/?page=1&limit=20 HTTP/1.1" 200 OK
INFO:     127.0.0.1:51902 - "GET /api/auth/me HTTP/1.1" 200 OK
INFO:     127.0.0.1:51904 - "GET /api/auth/me HTTP/1.1" 200 OK
INFO:     127.0.0.1:51900 - "GET /api/orders/?page=1&limit=20 HTTP/1.1" 200 OK
INFO:     127.0.0.1:51932 - "GET /api/auth/me HTTP/1.1" 200 OK
INFO:     127.0.0.1:51934 - "GET /api/auth/me HTTP/1.1" 200 OK
INFO:     127.0.0.1:51931 - "GET /api/orders/?page=1&limit=20 HTTP/1.1" 200 OK
INFO:     127.0.0.1:52001 - "GET /api/auth/me HTTP/1.1" 200 OK
INFO:     127.0.0.1:52000 - "GET /api/orders/?page=1&limit=20 HTTP/1.1" 200 OK
INFO:     127.0.0.1:52003 - "GET /api/auth/me HTTP/1.1" 200 OK
INFO:     127.0.0.1:52032 - "GET /api/auth/me HTTP/1.1" 200 OK
INFO:     127.0.0.1:52030 - "GET /api/orders/?page=1&limit=20 HTTP/1.1" 200 OK
INFO:     127.0.0.1:52034 - "GET /api/auth/me HTTP/1.1" 200 OK
INFO:     127.0.0.1:52055 - "GET /api/products/ HTTP/1.1" 200 OK
INFO:     127.0.0.1:52083 - "GET /api/auth/me HTTP/1.1" 200 OK
INFO:     127.0.0.1:52082 - "GET /api/orders/?page=1&limit=20 HTTP/1.1" 200 OK
INFO:     127.0.0.1:52085 - "GET /api/auth/me HTTP/1.1" 200 OK
INFO:     127.0.0.1:52087 - "GET /api/warehouse/?page=1&limit=20 HTTP/1.1" 200 OK
INFO:     127.0.0.1:52089 - "GET /api/customers/?limit=20&skip=0 HTTP/1.1" 200 OK
INFO:     127.0.0.1:52091 - "GET /api/warehouse/?page=1&limit=20 HTTP/1.1" 200 OK
INFO:     127.0.0.1:52113 - "GET /api/customers/?limit=20&skip=0 HTTP/1.1" 200 OK
INFO:     127.0.0.1:52124 - "GET /api/auth/me HTTP/1.1" 200 OK
INFO:     127.0.0.1:52126 - "GET /api/auth/me HTTP/1.1" 200 OK
INFO:     127.0.0.1:52122 - "GET /api/customers/?limit=20&skip=0 HTTP/1.1" 200 OK
INFO:     127.0.0.1:52134 - "GET /api/auth/me HTTP/1.1" 200 OK
INFO:     127.0.0.1:52136 - "GET /api/auth/me HTTP/1.1" 200 OK
INFO:     127.0.0.1:52133 - "GET /api/customers/?limit=20&skip=0 HTTP/1.1" 200 OK
INFO:     127.0.0.1:52138 - "GET /api/warehouse/?page=1&limit=20 HTTP/1.1" 200 OK
INFO:     127.0.0.1:52141 - "GET /api/orders/?page=1&limit=20 HTTP/1.1" 200 OK
INFO:     127.0.0.1:52150 - "GET /api/auth/me HTTP/1.1" 200 OK
INFO:     127.0.0.1:52151 - "GET /api/orders/?page=1&limit=20 HTTP/1.1" 200 OK
INFO:     127.0.0.1:52153 - "GET /api/auth/me HTTP/1.1" 200 OK
INFO:     127.0.0.1:52248 - "GET /api/auth/me HTTP/1.1" 200 OK
INFO:     127.0.0.1:52247 - "GET /api/orders/?page=1&limit=20 HTTP/1.1" 200 OK
INFO:     127.0.0.1:52250 - "GET /api/auth/me HTTP/1.1" 200 OK
INFO:     127.0.0.1:52276 - "GET /api/auth/me HTTP/1.1" 200 OK
INFO:     127.0.0.1:52275 - "GET /api/orders/?page=1&limit=20 HTTP/1.1" 200 OK
INFO:     127.0.0.1:52278 - "GET /api/auth/me HTTP/1.1" 200 OK
INFO:     127.0.0.1:52308 - "GET /api/auth/me HTTP/1.1" 200 OK
INFO:     127.0.0.1:52307 - "GET /api/orders/?page=1&limit=20 HTTP/1.1" 200 OK
INFO:     127.0.0.1:52310 - "GET /api/auth/me HTTP/1.1" 200 OK
INFO:     127.0.0.1:52312 - "GET /api/customers/?limit=20&skip=0 HTTP/1.1" 200 OK
INFO:     127.0.0.1:52321 - "GET /api/auth/me HTTP/1.1" 200 OK
INFO:     127.0.0.1:52323 - "GET /api/auth/me HTTP/1.1" 200 OK
INFO:     127.0.0.1:52319 - "GET /api/customers/?limit=20&skip=0 HTTP/1.1" 200 OK
INFO:     127.0.0.1:52325 - "GET /api/warehouse/?page=1&limit=20 HTTP/1.1" 200 OK
INFO:     127.0.0.1:52327 - "GET /api/orders/?page=1&limit=20 HTTP/1.1" 200 OK
INFO:     127.0.0.1:52337 - "GET /api/auth/me HTTP/1.1" 200 OK
INFO:     127.0.0.1:52335 - "GET /api/orders/?page=1&limit=20 HTTP/1.1" 200 OK
INFO:     127.0.0.1:52339 - "GET /api/auth/me HTTP/1.1" 200 OK
INFO:     127.0.0.1:52344 - "GET /api/products/ HTTP/1.1" 200 OK
INFO:     127.0.0.1:52386 - "GET /api/warehouse/?page=1&limit=20 HTTP/1.1" 200 OK
INFO:     127.0.0.1:52389 - "GET /api/customers/?limit=20&skip=0 HTTP/1.1" 200 OK
INFO:     127.0.0.1:52400 - "GET /api/auth/me HTTP/1.1" 200 OK
INFO:     127.0.0.1:52402 - "GET /api/auth/me HTTP/1.1" 200 OK
INFO:     127.0.0.1:52398 - "GET /api/customers/?limit=20&skip=0 HTTP/1.1" 200 OK
INFO:     127.0.0.1:52424 - "GET /api/warehouse/?page=1&limit=20 HTTP/1.1" 200 OK
INFO:     127.0.0.1:52426 - "GET /api/customers/?limit=20&skip=0 HTTP/1.1" 200 OK
INFO:     127.0.0.1:52436 - "GET /api/auth/me HTTP/1.1" 200 OK
INFO:     127.0.0.1:52438 - "GET /api/auth/me HTTP/1.1" 200 OK
INFO:     127.0.0.1:52434 - "GET /api/customers/?limit=20&skip=0 HTTP/1.1" 200 OK
INFO:     127.0.0.1:52446 - "GET /api/auth/me HTTP/1.1" 200 OK
INFO:     127.0.0.1:52448 - "GET /api/auth/me HTTP/1.1" 200 OK
INFO:     127.0.0.1:52445 - "GET /api/customers/?limit=20&skip=0 HTTP/1.1" 200 OK
INFO:     127.0.0.1:52456 - "GET /api/auth/me HTTP/1.1" 200 OK
INFO:     127.0.0.1:52458 - "GET /api/auth/me HTTP/1.1" 200 OK
INFO:     127.0.0.1:52455 - "GET /api/customers/?limit=20&skip=0 HTTP/1.1" 200 OK
INFO:app.services.otp_service:OTP generated for phone: +77051234567
INFO:     127.0.0.1:52462 - "POST /api/auth/request-otp HTTP/1.1" 201 Created
INFO:     127.0.0.1:52482 - "POST /api/auth/verify-otp HTTP/1.1" 500 Internal Server Error
ERROR:    Exception in ASGI application
Traceback (most recent call last):
  File "/Users/alekenov/projects/shadcn-test/backend/venv/lib/python3.9/site-packages/sqlalchemy/engine/base.py", line 1969, in _exec_single_context
    self.dialect.do_execute(
  File "/Users/alekenov/projects/shadcn-test/backend/venv/lib/python3.9/site-packages/sqlalchemy/engine/default.py", line 922, in do_execute
    cursor.execute(statement, parameters)
sqlite3.OperationalError: attempt to write a readonly database

The above exception was the direct cause of the following exception:

Traceback (most recent call last):
  File "/Users/alekenov/projects/shadcn-test/backend/venv/lib/python3.9/site-packages/uvicorn/protocols/http/httptools_impl.py", line 426, in run_asgi
    result = await app(  # type: ignore[func-returns-value]
  File "/Users/alekenov/projects/shadcn-test/backend/venv/lib/python3.9/site-packages/uvicorn/middleware/proxy_headers.py", line 84, in __call__
    return await self.app(scope, receive, send)
  File "/Users/alekenov/projects/shadcn-test/backend/venv/lib/python3.9/site-packages/fastapi/applications.py", line 1054, in __call__
    await super().__call__(scope, receive, send)
  File "/Users/alekenov/projects/shadcn-test/backend/venv/lib/python3.9/site-packages/starlette/applications.py", line 123, in __call__
    await self.middleware_stack(scope, receive, send)
  File "/Users/alekenov/projects/shadcn-test/backend/venv/lib/python3.9/site-packages/starlette/middleware/errors.py", line 186, in __call__
    raise exc
  File "/Users/alekenov/projects/shadcn-test/backend/venv/lib/python3.9/site-packages/starlette/middleware/errors.py", line 164, in __call__
    await self.app(scope, receive, _send)
  File "/Users/alekenov/projects/shadcn-test/backend/venv/lib/python3.9/site-packages/starlette/middleware/cors.py", line 83, in __call__
    await self.app(scope, receive, send)
  File "/Users/alekenov/projects/shadcn-test/backend/venv/lib/python3.9/site-packages/starlette/middleware/exceptions.py", line 62, in __call__
    await wrap_app_handling_exceptions(self.app, conn)(scope, receive, send)
  File "/Users/alekenov/projects/shadcn-test/backend/venv/lib/python3.9/site-packages/starlette/_exception_handler.py", line 64, in wrapped_app
    raise exc
  File "/Users/alekenov/projects/shadcn-test/backend/venv/lib/python3.9/site-packages/starlette/_exception_handler.py", line 53, in wrapped_app
    await app(scope, receive, sender)
  File "/Users/alekenov/projects/shadcn-test/backend/venv/lib/python3.9/site-packages/starlette/routing.py", line 762, in __call__
    await self.middleware_stack(scope, receive, send)
  File "/Users/alekenov/projects/shadcn-test/backend/venv/lib/python3.9/site-packages/starlette/routing.py", line 782, in app
    await route.handle(scope, receive, send)
  File "/Users/alekenov/projects/shadcn-test/backend/venv/lib/python3.9/site-packages/starlette/routing.py", line 297, in handle
    await self.app(scope, receive, send)
  File "/Users/alekenov/projects/shadcn-test/backend/venv/lib/python3.9/site-packages/starlette/routing.py", line 77, in app
    await wrap_app_handling_exceptions(app, request)(scope, receive, send)
  File "/Users/alekenov/projects/shadcn-test/backend/venv/lib/python3.9/site-packages/starlette/_exception_handler.py", line 64, in wrapped_app
    raise exc
  File "/Users/alekenov/projects/shadcn-test/backend/venv/lib/python3.9/site-packages/starlette/_exception_handler.py", line 53, in wrapped_app
    await app(scope, receive, sender)
  File "/Users/alekenov/projects/shadcn-test/backend/venv/lib/python3.9/site-packages/starlette/routing.py", line 72, in app
    response = await func(request)
  File "/Users/alekenov/projects/shadcn-test/backend/venv/lib/python3.9/site-packages/fastapi/routing.py", line 299, in app
    raise e
  File "/Users/alekenov/projects/shadcn-test/backend/venv/lib/python3.9/site-packages/fastapi/routing.py", line 294, in app
    raw_response = await run_endpoint_function(
  File "/Users/alekenov/projects/shadcn-test/backend/venv/lib/python3.9/site-packages/fastapi/routing.py", line 191, in run_endpoint_function
    return await dependant.call(**values)
  File "/Users/alekenov/projects/shadcn-test/backend/app/api/endpoints/auth.py", line 118, in verify_otp
    shop = crud_shop.create(db, obj_in=shop_data)
  File "/Users/alekenov/projects/shadcn-test/backend/app/crud/shop.py", line 41, in create
    db.commit()
  File "/Users/alekenov/projects/shadcn-test/backend/venv/lib/python3.9/site-packages/sqlalchemy/orm/session.py", line 1969, in commit
    trans.commit(_to_root=True)
  File "<string>", line 2, in commit
  File "/Users/alekenov/projects/shadcn-test/backend/venv/lib/python3.9/site-packages/sqlalchemy/orm/state_changes.py", line 139, in _go
    ret_value = fn(self, *arg, **kw)
  File "/Users/alekenov/projects/shadcn-test/backend/venv/lib/python3.9/site-packages/sqlalchemy/orm/session.py", line 1256, in commit
    self._prepare_impl()
  File "<string>", line 2, in _prepare_impl
  File "/Users/alekenov/projects/shadcn-test/backend/venv/lib/python3.9/site-packages/sqlalchemy/orm/state_changes.py", line 139, in _go
    ret_value = fn(self, *arg, **kw)
  File "/Users/alekenov/projects/shadcn-test/backend/venv/lib/python3.9/site-packages/sqlalchemy/orm/session.py", line 1231, in _prepare_impl
    self.session.flush()
  File "/Users/alekenov/projects/shadcn-test/backend/venv/lib/python3.9/site-packages/sqlalchemy/orm/session.py", line 4312, in flush
    self._flush(objects)
  File "/Users/alekenov/projects/shadcn-test/backend/venv/lib/python3.9/site-packages/sqlalchemy/orm/session.py", line 4448, in _flush
    transaction.rollback(_capture_exception=True)
  File "/Users/alekenov/projects/shadcn-test/backend/venv/lib/python3.9/site-packages/sqlalchemy/util/langhelpers.py", line 146, in __exit__
    raise exc_value.with_traceback(exc_tb)
  File "/Users/alekenov/projects/shadcn-test/backend/venv/lib/python3.9/site-packages/sqlalchemy/orm/session.py", line 4408, in _flush
    flush_context.execute()
  File "/Users/alekenov/projects/shadcn-test/backend/venv/lib/python3.9/site-packages/sqlalchemy/orm/unitofwork.py", line 466, in execute
    rec.execute(self)
  File "/Users/alekenov/projects/shadcn-test/backend/venv/lib/python3.9/site-packages/sqlalchemy/orm/unitofwork.py", line 642, in execute
    util.preloaded.orm_persistence.save_obj(
  File "/Users/alekenov/projects/shadcn-test/backend/venv/lib/python3.9/site-packages/sqlalchemy/orm/persistence.py", line 93, in save_obj
    _emit_insert_statements(
  File "/Users/alekenov/projects/shadcn-test/backend/venv/lib/python3.9/site-packages/sqlalchemy/orm/persistence.py", line 1226, in _emit_insert_statements
    result = connection.execute(
  File "/Users/alekenov/projects/shadcn-test/backend/venv/lib/python3.9/site-packages/sqlalchemy/engine/base.py", line 1416, in execute
    return meth(
  File "/Users/alekenov/projects/shadcn-test/backend/venv/lib/python3.9/site-packages/sqlalchemy/sql/elements.py", line 516, in _execute_on_connection
    return connection._execute_clauseelement(
  File "/Users/alekenov/projects/shadcn-test/backend/venv/lib/python3.9/site-packages/sqlalchemy/engine/base.py", line 1639, in _execute_clauseelement
    ret = self._execute_context(
  File "/Users/alekenov/projects/shadcn-test/backend/venv/lib/python3.9/site-packages/sqlalchemy/engine/base.py", line 1848, in _execute_context
    return self._exec_single_context(
  File "/Users/alekenov/projects/shadcn-test/backend/venv/lib/python3.9/site-packages/sqlalchemy/engine/base.py", line 1988, in _exec_single_context
    self._handle_dbapi_exception(
  File "/Users/alekenov/projects/shadcn-test/backend/venv/lib/python3.9/site-packages/sqlalchemy/engine/base.py", line 2343, in _handle_dbapi_exception
    raise sqlalchemy_exception.with_traceback(exc_info[2]) from e
  File "/Users/alekenov/projects/shadcn-test/backend/venv/lib/python3.9/site-packages/sqlalchemy/engine/base.py", line 1969, in _exec_single_context
    self.dialect.do_execute(
  File "/Users/alekenov/projects/shadcn-test/backend/venv/lib/python3.9/site-packages/sqlalchemy/engine/default.py", line 922, in do_execute
    cursor.execute(statement, parameters)
sqlalchemy.exc.OperationalError: (sqlite3.OperationalError) attempt to write a readonly database
[SQL: INSERT INTO shops (name, phone, email, telegram_id, telegram_username, address, city, description, business_hours, currency, timezone, language, is_active, is_verified, "plan", trial_ends_at, last_login_at) VALUES (?, ?, ?, ?, ?, ?, ?, ?, ?, ?, ?, ?, ?, ?, ?, ?, ?) RETURNING id, created_at, updated_at]
[parameters: ('Цветочный магазин 4567', '+77051234567', None, None, None, None, 'Алматы', None, 'null', 'KZT', 'Asia/Almaty', 'ru', 1, 0, 'basic', None, None)]
(Background on this error at: https://sqlalche.me/e/20/e3q8)
INFO:     127.0.0.1:52511 - "GET /api/auth/me HTTP/1.1" 200 OK
INFO:     127.0.0.1:52510 - "GET /api/products/ HTTP/1.1" 200 OK
INFO:     127.0.0.1:52513 - "GET /api/auth/me HTTP/1.1" 200 OK
INFO:     127.0.0.1:52515 - "GET /api/products/ HTTP/1.1" 200 OK
INFO:     127.0.0.1:52517 - "GET /api/products/ HTTP/1.1" 200 OK
INFO:     127.0.0.1:52519 - "GET /api/products/ HTTP/1.1" 200 OK
INFO:     127.0.0.1:52543 - "GET /api/auth/me HTTP/1.1" 200 OK
INFO:     127.0.0.1:52544 - "GET /api/orders/?page=1&limit=20 HTTP/1.1" 200 OK
INFO:     127.0.0.1:52546 - "GET /api/auth/me HTTP/1.1" 200 OK
INFO:     127.0.0.1:52567 - "GET /api/auth/me HTTP/1.1" 200 OK
INFO:     127.0.0.1:52569 - "GET /api/auth/me HTTP/1.1" 200 OK
INFO:     127.0.0.1:52565 - "GET /api/customers/?limit=20&skip=0 HTTP/1.1" 200 OK
INFO:     127.0.0.1:52933 - "GET /api/auth/me HTTP/1.1" 200 OK
INFO:     127.0.0.1:52936 - "GET /api/auth/me HTTP/1.1" 200 OK
INFO:     127.0.0.1:52934 - "GET /api/customers/?limit=20&skip=0 HTTP/1.1" 200 OK
INFO:     127.0.0.1:52973 - "GET /api/auth/me HTTP/1.1" 200 OK
INFO:     127.0.0.1:52975 - "GET /api/auth/me HTTP/1.1" 200 OK
INFO:     127.0.0.1:52972 - "GET /api/customers/?limit=20&skip=0 HTTP/1.1" 200 OK
INFO:     127.0.0.1:53003 - "GET /api/orders/?page=1&limit=20 HTTP/1.1" 200 OK
INFO:     127.0.0.1:53006 - "GET /api/warehouse/?page=1&limit=20 HTTP/1.1" 200 OK
INFO:     127.0.0.1:53009 - "GET /api/customers/?limit=20&skip=0 HTTP/1.1" 200 OK
INFO:     127.0.0.1:53012 - "GET /api/warehouse/?page=1&limit=20 HTTP/1.1" 200 OK
INFO:     127.0.0.1:53015 - "GET /api/orders/?page=1&limit=20 HTTP/1.1" 200 OK
INFO:     127.0.0.1:53018 - "GET /api/warehouse/?page=1&limit=20 HTTP/1.1" 200 OK
INFO:     127.0.0.1:53021 - "GET /api/customers/?limit=20&skip=0 HTTP/1.1" 200 OK
INFO:     127.0.0.1:53144 - "GET /api/auth/me HTTP/1.1" 200 OK
INFO:     127.0.0.1:53146 - "GET /api/auth/me HTTP/1.1" 200 OK
INFO:     127.0.0.1:53143 - "GET /api/customers/?limit=20&skip=0 HTTP/1.1" 200 OK
INFO:     127.0.0.1:53182 - "GET /api/auth/me HTTP/1.1" 200 OK
INFO:     127.0.0.1:53184 - "GET /api/auth/me HTTP/1.1" 200 OK
INFO:     127.0.0.1:53180 - "GET /api/customers/?limit=20&skip=0 HTTP/1.1" 200 OK
INFO:     127.0.0.1:53188 - "GET /api/warehouse/?page=1&limit=20 HTTP/1.1" 200 OK
INFO:     127.0.0.1:53191 - "GET /api/orders/?page=1&limit=20 HTTP/1.1" 200 OK
INFO:     127.0.0.1:53194 - "GET /api/warehouse/?page=1&limit=20 HTTP/1.1" 200 OK
INFO:     127.0.0.1:53198 - "GET /api/customers/?limit=20&skip=0 HTTP/1.1" 200 OK
INFO:     127.0.0.1:53291 - "GET /api/orders/?page=1&limit=20 HTTP/1.1" 200 OK
INFO:     127.0.0.1:53294 - "GET /api/customers/?limit=20&skip=0 HTTP/1.1" 200 OK
INFO:     127.0.0.1:53332 - "GET /api/auth/me HTTP/1.1" 200 OK
INFO:     127.0.0.1:53330 - "GET /api/orders/?page=1&limit=20 HTTP/1.1" 200 OK
INFO:     127.0.0.1:53334 - "GET /api/auth/me HTTP/1.1" 200 OK
INFO:     127.0.0.1:53355 - "GET /api/auth/me HTTP/1.1" 200 OK
INFO:     127.0.0.1:53356 - "GET /api/orders/?page=1&limit=20 HTTP/1.1" 200 OK
INFO:     127.0.0.1:53358 - "GET /api/auth/me HTTP/1.1" 200 OK
INFO:     127.0.0.1:53366 - "GET /api/auth/me HTTP/1.1" 200 OK
INFO:     127.0.0.1:53368 - "GET /api/auth/me HTTP/1.1" 200 OK
INFO:     127.0.0.1:53365 - "GET /api/customers/?limit=20&skip=0 HTTP/1.1" 200 OK
INFO:     127.0.0.1:53379 - "GET /api/auth/me HTTP/1.1" 200 OK
INFO:     127.0.0.1:53381 - "GET /api/auth/me HTTP/1.1" 200 OK
INFO:     127.0.0.1:53378 - "GET /api/customers/?limit=20&skip=0 HTTP/1.1" 200 OK
INFO:     127.0.0.1:53408 - "GET /api/orders/ HTTP/1.1" 403 Forbidden
INFO:app.services.otp_service:OTP generated for phone: +77051234567
INFO:     127.0.0.1:53455 - "POST /api/auth/request-otp HTTP/1.1" 201 Created
INFO:     127.0.0.1:53492 - "POST /api/auth/verify-otp HTTP/1.1" 500 Internal Server Error
ERROR:    Exception in ASGI application
Traceback (most recent call last):
  File "/Users/alekenov/projects/shadcn-test/backend/venv/lib/python3.9/site-packages/sqlalchemy/engine/base.py", line 1969, in _exec_single_context
    self.dialect.do_execute(
  File "/Users/alekenov/projects/shadcn-test/backend/venv/lib/python3.9/site-packages/sqlalchemy/engine/default.py", line 922, in do_execute
    cursor.execute(statement, parameters)
sqlite3.OperationalError: attempt to write a readonly database

The above exception was the direct cause of the following exception:

Traceback (most recent call last):
  File "/Users/alekenov/projects/shadcn-test/backend/venv/lib/python3.9/site-packages/uvicorn/protocols/http/httptools_impl.py", line 426, in run_asgi
    result = await app(  # type: ignore[func-returns-value]
  File "/Users/alekenov/projects/shadcn-test/backend/venv/lib/python3.9/site-packages/uvicorn/middleware/proxy_headers.py", line 84, in __call__
    return await self.app(scope, receive, send)
  File "/Users/alekenov/projects/shadcn-test/backend/venv/lib/python3.9/site-packages/fastapi/applications.py", line 1054, in __call__
    await super().__call__(scope, receive, send)
  File "/Users/alekenov/projects/shadcn-test/backend/venv/lib/python3.9/site-packages/starlette/applications.py", line 123, in __call__
    await self.middleware_stack(scope, receive, send)
  File "/Users/alekenov/projects/shadcn-test/backend/venv/lib/python3.9/site-packages/starlette/middleware/errors.py", line 186, in __call__
    raise exc
  File "/Users/alekenov/projects/shadcn-test/backend/venv/lib/python3.9/site-packages/starlette/middleware/errors.py", line 164, in __call__
    await self.app(scope, receive, _send)
  File "/Users/alekenov/projects/shadcn-test/backend/venv/lib/python3.9/site-packages/starlette/middleware/cors.py", line 91, in __call__
    await self.simple_response(scope, receive, send, request_headers=headers)
  File "/Users/alekenov/projects/shadcn-test/backend/venv/lib/python3.9/site-packages/starlette/middleware/cors.py", line 146, in simple_response
    await self.app(scope, receive, send)
  File "/Users/alekenov/projects/shadcn-test/backend/venv/lib/python3.9/site-packages/starlette/middleware/exceptions.py", line 62, in __call__
    await wrap_app_handling_exceptions(self.app, conn)(scope, receive, send)
  File "/Users/alekenov/projects/shadcn-test/backend/venv/lib/python3.9/site-packages/starlette/_exception_handler.py", line 64, in wrapped_app
    raise exc
  File "/Users/alekenov/projects/shadcn-test/backend/venv/lib/python3.9/site-packages/starlette/_exception_handler.py", line 53, in wrapped_app
    await app(scope, receive, sender)
  File "/Users/alekenov/projects/shadcn-test/backend/venv/lib/python3.9/site-packages/starlette/routing.py", line 762, in __call__
    await self.middleware_stack(scope, receive, send)
  File "/Users/alekenov/projects/shadcn-test/backend/venv/lib/python3.9/site-packages/starlette/routing.py", line 782, in app
    await route.handle(scope, receive, send)
  File "/Users/alekenov/projects/shadcn-test/backend/venv/lib/python3.9/site-packages/starlette/routing.py", line 297, in handle
    await self.app(scope, receive, send)
  File "/Users/alekenov/projects/shadcn-test/backend/venv/lib/python3.9/site-packages/starlette/routing.py", line 77, in app
    await wrap_app_handling_exceptions(app, request)(scope, receive, send)
  File "/Users/alekenov/projects/shadcn-test/backend/venv/lib/python3.9/site-packages/starlette/_exception_handler.py", line 64, in wrapped_app
    raise exc
  File "/Users/alekenov/projects/shadcn-test/backend/venv/lib/python3.9/site-packages/starlette/_exception_handler.py", line 53, in wrapped_app
    await app(scope, receive, sender)
  File "/Users/alekenov/projects/shadcn-test/backend/venv/lib/python3.9/site-packages/starlette/routing.py", line 72, in app
    response = await func(request)
  File "/Users/alekenov/projects/shadcn-test/backend/venv/lib/python3.9/site-packages/fastapi/routing.py", line 299, in app
    raise e
  File "/Users/alekenov/projects/shadcn-test/backend/venv/lib/python3.9/site-packages/fastapi/routing.py", line 294, in app
    raw_response = await run_endpoint_function(
  File "/Users/alekenov/projects/shadcn-test/backend/venv/lib/python3.9/site-packages/fastapi/routing.py", line 191, in run_endpoint_function
    return await dependant.call(**values)
  File "/Users/alekenov/projects/shadcn-test/backend/app/api/endpoints/auth.py", line 118, in verify_otp
    shop = crud_shop.create(db, obj_in=shop_data)
  File "/Users/alekenov/projects/shadcn-test/backend/app/crud/shop.py", line 41, in create
    db.commit()
  File "/Users/alekenov/projects/shadcn-test/backend/venv/lib/python3.9/site-packages/sqlalchemy/orm/session.py", line 1969, in commit
    trans.commit(_to_root=True)
  File "<string>", line 2, in commit
  File "/Users/alekenov/projects/shadcn-test/backend/venv/lib/python3.9/site-packages/sqlalchemy/orm/state_changes.py", line 139, in _go
    ret_value = fn(self, *arg, **kw)
  File "/Users/alekenov/projects/shadcn-test/backend/venv/lib/python3.9/site-packages/sqlalchemy/orm/session.py", line 1256, in commit
    self._prepare_impl()
  File "<string>", line 2, in _prepare_impl
  File "/Users/alekenov/projects/shadcn-test/backend/venv/lib/python3.9/site-packages/sqlalchemy/orm/state_changes.py", line 139, in _go
    ret_value = fn(self, *arg, **kw)
  File "/Users/alekenov/projects/shadcn-test/backend/venv/lib/python3.9/site-packages/sqlalchemy/orm/session.py", line 1231, in _prepare_impl
    self.session.flush()
  File "/Users/alekenov/projects/shadcn-test/backend/venv/lib/python3.9/site-packages/sqlalchemy/orm/session.py", line 4312, in flush
    self._flush(objects)
  File "/Users/alekenov/projects/shadcn-test/backend/venv/lib/python3.9/site-packages/sqlalchemy/orm/session.py", line 4448, in _flush
    transaction.rollback(_capture_exception=True)
  File "/Users/alekenov/projects/shadcn-test/backend/venv/lib/python3.9/site-packages/sqlalchemy/util/langhelpers.py", line 146, in __exit__
    raise exc_value.with_traceback(exc_tb)
  File "/Users/alekenov/projects/shadcn-test/backend/venv/lib/python3.9/site-packages/sqlalchemy/orm/session.py", line 4408, in _flush
    flush_context.execute()
  File "/Users/alekenov/projects/shadcn-test/backend/venv/lib/python3.9/site-packages/sqlalchemy/orm/unitofwork.py", line 466, in execute
    rec.execute(self)
  File "/Users/alekenov/projects/shadcn-test/backend/venv/lib/python3.9/site-packages/sqlalchemy/orm/unitofwork.py", line 642, in execute
    util.preloaded.orm_persistence.save_obj(
  File "/Users/alekenov/projects/shadcn-test/backend/venv/lib/python3.9/site-packages/sqlalchemy/orm/persistence.py", line 93, in save_obj
    _emit_insert_statements(
  File "/Users/alekenov/projects/shadcn-test/backend/venv/lib/python3.9/site-packages/sqlalchemy/orm/persistence.py", line 1226, in _emit_insert_statements
    result = connection.execute(
  File "/Users/alekenov/projects/shadcn-test/backend/venv/lib/python3.9/site-packages/sqlalchemy/engine/base.py", line 1416, in execute
    return meth(
  File "/Users/alekenov/projects/shadcn-test/backend/venv/lib/python3.9/site-packages/sqlalchemy/sql/elements.py", line 516, in _execute_on_connection
    return connection._execute_clauseelement(
  File "/Users/alekenov/projects/shadcn-test/backend/venv/lib/python3.9/site-packages/sqlalchemy/engine/base.py", line 1639, in _execute_clauseelement
    ret = self._execute_context(
  File "/Users/alekenov/projects/shadcn-test/backend/venv/lib/python3.9/site-packages/sqlalchemy/engine/base.py", line 1848, in _execute_context
    return self._exec_single_context(
  File "/Users/alekenov/projects/shadcn-test/backend/venv/lib/python3.9/site-packages/sqlalchemy/engine/base.py", line 1988, in _exec_single_context
    self._handle_dbapi_exception(
  File "/Users/alekenov/projects/shadcn-test/backend/venv/lib/python3.9/site-packages/sqlalchemy/engine/base.py", line 2343, in _handle_dbapi_exception
    raise sqlalchemy_exception.with_traceback(exc_info[2]) from e
  File "/Users/alekenov/projects/shadcn-test/backend/venv/lib/python3.9/site-packages/sqlalchemy/engine/base.py", line 1969, in _exec_single_context
    self.dialect.do_execute(
  File "/Users/alekenov/projects/shadcn-test/backend/venv/lib/python3.9/site-packages/sqlalchemy/engine/default.py", line 922, in do_execute
    cursor.execute(statement, parameters)
sqlalchemy.exc.OperationalError: (sqlite3.OperationalError) attempt to write a readonly database
[SQL: INSERT INTO shops (name, phone, email, telegram_id, telegram_username, address, city, description, business_hours, currency, timezone, language, is_active, is_verified, "plan", trial_ends_at, last_login_at) VALUES (?, ?, ?, ?, ?, ?, ?, ?, ?, ?, ?, ?, ?, ?, ?, ?, ?) RETURNING id, created_at, updated_at]
[parameters: ('Цветочный магазин 4567', '+77051234567', None, None, None, None, 'Алматы', None, 'null', 'KZT', 'Asia/Almaty', 'ru', 1, 0, 'basic', None, None)]
(Background on this error at: https://sqlalche.me/e/20/e3q8)
INFO:     127.0.0.1:53743 - "POST /api/auth/test-code HTTP/1.1" 405 Method Not Allowed
